/*
 *** MADE BY MITHION'S .SCHEMATIC TO JAVA CONVERTING TOOL v1.6 ***
 * Size: 26 x 15 x 35
 */

package PorkerCraft.core.gen;

import java.util.Random;

import net.minecraft.world.World;
import net.minecraft.world.gen.feature.WorldGenerator;

public class MapGenBossTempleExterior extends WorldGenerator {
	public MapGenBossTempleExterior() {
	}

	public boolean generate1(World world, Random rand, int i, int j, int k) {
		world.setBlock(i + 0, j + 0, k + 0, 98, 0, 4);
		world.setBlock(i + 0, j + 0, k + 1, 98, 0, 4);
		world.setBlock(i + 0, j + 0, k + 2, 98, 0, 4);
		world.setBlock(i + 0, j + 0, k + 3, 98, 0, 4);
		world.setBlock(i + 0, j + 0, k + 4, 98, 0, 4);
		world.setBlock(i + 0, j + 0, k + 5, 98, 0, 4);
		world.setBlock(i + 0, j + 0, k + 6, 98, 0, 4);
		world.setBlock(i + 0, j + 0, k + 7, 98, 0, 4);
		world.setBlock(i + 0, j + 0, k + 8, 98, 0, 4);
		world.setBlock(i + 0, j + 0, k + 9, 98, 0, 4);
		world.setBlock(i + 0, j + 0, k + 10, 98, 0, 4);
		world.setBlock(i + 0, j + 0, k + 11, 98, 0, 4);
		world.setBlock(i + 0, j + 0, k + 12, 98, 0, 4);
		world.setBlock(i + 0, j + 0, k + 13, 98, 0, 4);
		world.setBlock(i + 0, j + 0, k + 14, 98, 0, 4);
		world.setBlock(i + 0, j + 0, k + 15, 98, 0, 4);
		world.setBlock(i + 0, j + 0, k + 16, 98, 0, 4);
		world.setBlock(i + 0, j + 0, k + 17, 98, 0, 4);
		world.setBlock(i + 0, j + 0, k + 18, 98, 0, 4);
		world.setBlock(i + 0, j + 0, k + 19, 98, 0, 4);
		world.setBlock(i + 0, j + 0, k + 20, 98, 0, 4);
		world.setBlock(i + 0, j + 0, k + 21, 98, 0, 4);
		world.setBlock(i + 0, j + 0, k + 22, 98, 0, 4);
		world.setBlock(i + 0, j + 0, k + 23, 98, 0, 4);
		world.setBlock(i + 0, j + 0, k + 24, 98, 0, 4);
		world.setBlock(i + 0, j + 0, k + 25, 98, 0, 4);
		world.setBlock(i + 0, j + 0, k + 26, 98, 0, 4);
		world.setBlock(i + 0, j + 0, k + 27, 98, 0, 4);
		world.setBlock(i + 0, j + 0, k + 28, 98, 0, 4);
		world.setBlock(i + 0, j + 0, k + 29, 98, 0, 4);
		world.setBlock(i + 0, j + 0, k + 30, 98, 0, 4);
		world.setBlock(i + 0, j + 0, k + 31, 98, 0, 4);
		world.setBlock(i + 0, j + 0, k + 32, 98, 0, 4);
		world.setBlock(i + 0, j + 0, k + 33, 98, 0, 4);
		world.setBlock(i + 0, j + 0, k + 34, 98, 0, 4);
		world.setBlock(i + 0, j + 1, k + 0, 98, 3, 3);
		world.setBlock(i + 0, j + 1, k + 34, 98, 3, 3);
		world.setBlock(i + 0, j + 2, k + 0, 98, 3, 3);
		world.setBlock(i + 0, j + 2, k + 34, 98, 3, 3);
		world.setBlock(i + 0, j + 3, k + 0, 98, 3, 3);
		world.setBlock(i + 0, j + 3, k + 34, 98, 3, 3);
		world.setBlock(i + 0, j + 4, k + 0, 98, 3, 3);
		world.setBlock(i + 0, j + 4, k + 34, 98, 3, 3);
		world.setBlock(i + 0, j + 5, k + 0, 98, 3, 3);
		world.setBlock(i + 0, j + 5, k + 34, 98, 3, 3);
		world.setBlock(i + 0, j + 6, k + 0, 98, 3, 3);
		world.setBlock(i + 0, j + 6, k + 34, 98, 3, 3);
		world.setBlock(i + 0, j + 7, k + 0, 98, 3, 3);
		world.setBlock(i + 0, j + 7, k + 1, 98, 3, 3);
		world.setBlock(i + 0, j + 7, k + 2, 98, 3, 3);
		world.setBlock(i + 0, j + 7, k + 3, 98, 3, 3);
		world.setBlock(i + 0, j + 7, k + 4, 98, 3, 3);
		world.setBlock(i + 0, j + 7, k + 5, 98, 3, 3);
		world.setBlock(i + 0, j + 7, k + 6, 98, 3, 3);
		world.setBlock(i + 0, j + 7, k + 7, 98, 3, 3);
		world.setBlock(i + 0, j + 7, k + 8, 98, 3, 3);
		world.setBlock(i + 0, j + 7, k + 9, 98, 3, 3);
		world.setBlock(i + 0, j + 7, k + 10, 98, 3, 3);
		world.setBlock(i + 0, j + 7, k + 11, 98, 3, 3);
		world.setBlock(i + 0, j + 7, k + 12, 98, 3, 3);
		world.setBlock(i + 0, j + 7, k + 13, 98, 3, 3);
		world.setBlock(i + 0, j + 7, k + 14, 98, 3, 3);
		world.setBlock(i + 0, j + 7, k + 15, 98, 3, 3);
		world.setBlock(i + 0, j + 7, k + 16, 98, 3, 3);
		world.setBlock(i + 0, j + 7, k + 17, 98, 3, 3);
		world.setBlock(i + 0, j + 7, k + 18, 98, 3, 3);
		world.setBlock(i + 0, j + 7, k + 19, 98, 3, 3);
		world.setBlock(i + 0, j + 7, k + 20, 98, 3, 3);
		world.setBlock(i + 0, j + 7, k + 21, 98, 3, 3);
		world.setBlock(i + 0, j + 7, k + 22, 98, 3, 3);
		world.setBlock(i + 0, j + 7, k + 23, 98, 3, 3);
		world.setBlock(i + 0, j + 7, k + 24, 98, 3, 3);
		world.setBlock(i + 0, j + 7, k + 25, 98, 3, 3);
		world.setBlock(i + 0, j + 7, k + 26, 98, 3, 3);
		world.setBlock(i + 0, j + 7, k + 27, 98, 3, 3);
		world.setBlock(i + 0, j + 7, k + 28, 98, 3, 3);
		world.setBlock(i + 0, j + 7, k + 29, 98, 3, 3);
		world.setBlock(i + 0, j + 7, k + 30, 98, 3, 3);
		world.setBlock(i + 0, j + 7, k + 31, 98, 3, 3);
		world.setBlock(i + 0, j + 7, k + 32, 98, 3, 3);
		world.setBlock(i + 0, j + 7, k + 33, 98, 3, 3);
		world.setBlock(i + 0, j + 7, k + 34, 98, 3, 3);
		world.setBlock(i + 0, j + 8, k + 0, 98, 3, 3);
		world.setBlock(i + 0, j + 8, k + 34, 98, 3, 3);
		world.setBlock(i + 0, j + 9, k + 0, 98, 3, 3);
		world.setBlock(i + 0, j + 9, k + 34, 98, 3, 3);
		world.setBlock(i + 0, j + 10, k + 0, 98, 3, 3);
		world.setBlock(i + 0, j + 10, k + 34, 98, 3, 3);
		world.setBlock(i + 0, j + 11, k + 0, 98, 3, 3);
		world.setBlock(i + 0, j + 11, k + 34, 98, 3, 3);
		world.setBlock(i + 0, j + 12, k + 0, 98, 3, 3);
		world.setBlock(i + 0, j + 12, k + 34, 98, 3, 3);
		world.setBlock(i + 0, j + 13, k + 0, 109, 2, 3);
		world.setBlock(i + 0, j + 13, k + 1, 109, 0, 4);
		world.setBlock(i + 0, j + 13, k + 2, 109, 0, 4);
		world.setBlock(i + 0, j + 13, k + 3, 109, 0, 4);
		world.setBlock(i + 0, j + 13, k + 4, 109, 0, 4);
		world.setBlock(i + 0, j + 13, k + 5, 109, 0, 4);
		world.setBlock(i + 0, j + 13, k + 6, 109, 0, 4);
		world.setBlock(i + 0, j + 13, k + 7, 109, 0, 4);
		world.setBlock(i + 0, j + 13, k + 8, 109, 0, 4);
		world.setBlock(i + 0, j + 13, k + 9, 109, 0, 4);
		world.setBlock(i + 0, j + 13, k + 10, 109, 0, 4);
		world.setBlock(i + 0, j + 13, k + 11, 109, 0, 4);
		world.setBlock(i + 0, j + 13, k + 12, 109, 0, 4);
		world.setBlock(i + 0, j + 13, k + 13, 109, 0, 4);
		world.setBlock(i + 0, j + 13, k + 14, 109, 0, 4);
		world.setBlock(i + 0, j + 13, k + 15, 109, 0, 4);
		world.setBlock(i + 0, j + 13, k + 16, 109, 0, 4);
		world.setBlock(i + 0, j + 13, k + 17, 109, 0, 4);
		world.setBlock(i + 0, j + 13, k + 18, 109, 0, 4);
		world.setBlock(i + 0, j + 13, k + 19, 109, 0, 4);
		world.setBlock(i + 0, j + 13, k + 20, 109, 0, 4);
		world.setBlock(i + 0, j + 13, k + 21, 109, 0, 4);
		world.setBlock(i + 0, j + 13, k + 22, 109, 0, 4);
		world.setBlock(i + 0, j + 13, k + 23, 109, 0, 4);
		world.setBlock(i + 0, j + 13, k + 24, 109, 0, 4);
		world.setBlock(i + 0, j + 13, k + 25, 109, 0, 4);
		world.setBlock(i + 0, j + 13, k + 26, 109, 0, 4);
		world.setBlock(i + 0, j + 13, k + 27, 109, 0, 4);
		world.setBlock(i + 0, j + 13, k + 28, 109, 0, 4);
		world.setBlock(i + 0, j + 13, k + 29, 109, 0, 4);
		world.setBlock(i + 0, j + 13, k + 30, 109, 0, 4);
		world.setBlock(i + 0, j + 13, k + 31, 109, 0, 4);
		world.setBlock(i + 0, j + 13, k + 32, 109, 0, 4);
		world.setBlock(i + 0, j + 13, k + 33, 109, 0, 4);
		world.setBlock(i + 0, j + 13, k + 34, 109, 3, 3);
		world.setBlock(i + 1, j + 0, k + 0, 98, 0, 4);
		world.setBlock(i + 1, j + 0, k + 1, 98, 1, 3);
		world.setBlock(i + 1, j + 0, k + 2, 98, 1, 3);
		world.setBlock(i + 1, j + 0, k + 3, 98, 2, 3);
		world.setBlock(i + 1, j + 0, k + 4, 98, 1, 3);
		world.setBlock(i + 1, j + 0, k + 5, 98, 1, 3);
		world.setBlock(i + 1, j + 0, k + 6, 98, 1, 3);
		world.setBlock(i + 1, j + 0, k + 7, 98, 1, 3);
		world.setBlock(i + 1, j + 0, k + 8, 98, 1, 3);
		world.setBlock(i + 1, j + 0, k + 9, 98, 1, 3);
		world.setBlock(i + 1, j + 0, k + 10, 98, 1, 3);
		world.setBlock(i + 1, j + 0, k + 11, 98, 1, 3);
		world.setBlock(i + 1, j + 0, k + 12, 98, 1, 3);
		world.setBlock(i + 1, j + 0, k + 13, 98, 1, 3);
		world.setBlock(i + 1, j + 0, k + 14, 98, 1, 3);
		world.setBlock(i + 1, j + 0, k + 15, 98, 1, 3);
		world.setBlock(i + 1, j + 0, k + 16, 98, 1, 3);
		world.setBlock(i + 1, j + 0, k + 17, 98, 1, 3);
		world.setBlock(i + 1, j + 0, k + 18, 98, 1, 3);
		world.setBlock(i + 1, j + 0, k + 19, 98, 1, 3);
		world.setBlock(i + 1, j + 0, k + 20, 98, 1, 3);
		world.setBlock(i + 1, j + 0, k + 21, 98, 1, 3);
		world.setBlock(i + 1, j + 0, k + 22, 98, 1, 3);
		world.setBlock(i + 1, j + 0, k + 23, 98, 1, 3);
		world.setBlock(i + 1, j + 0, k + 24, 98, 1, 3);
		world.setBlock(i + 1, j + 0, k + 25, 98, 1, 3);
		world.setBlock(i + 1, j + 0, k + 26, 98, 1, 3);
		world.setBlock(i + 1, j + 0, k + 27, 98, 1, 3);
		world.setBlock(i + 1, j + 0, k + 28, 98, 1, 3);
		world.setBlock(i + 1, j + 0, k + 29, 98, 1, 3);
		world.setBlock(i + 1, j + 0, k + 30, 98, 1, 3);
		world.setBlock(i + 1, j + 0, k + 31, 98, 1, 3);
		world.setBlock(i + 1, j + 0, k + 32, 98, 1, 3);
		world.setBlock(i + 1, j + 0, k + 33, 98, 1, 3);
		world.setBlock(i + 1, j + 0, k + 34, 98, 0, 4);
		world.setBlock(i + 1, j + 7, k + 0, 98, 3, 3);
		world.setBlock(i + 1, j + 7, k + 1, 98, 1, 3);
		world.setBlock(i + 1, j + 7, k + 2, 98, 1, 3);
		world.setBlock(i + 1, j + 7, k + 3, 98, 2, 3);
		world.setBlock(i + 1, j + 7, k + 4, 98, 1, 3);
		world.setBlock(i + 1, j + 7, k + 5, 98, 1, 3);
		world.setBlock(i + 1, j + 7, k + 6, 98, 1, 3);
		world.setBlock(i + 1, j + 7, k + 7, 98, 1, 3);
		world.setBlock(i + 1, j + 7, k + 8, 98, 1, 3);
		world.setBlock(i + 1, j + 7, k + 9, 98, 1, 3);
		world.setBlock(i + 1, j + 7, k + 10, 98, 1, 3);
		world.setBlock(i + 1, j + 7, k + 11, 98, 1, 3);
		world.setBlock(i + 1, j + 7, k + 12, 98, 1, 3);
		world.setBlock(i + 1, j + 7, k + 13, 98, 1, 3);
		world.setBlock(i + 1, j + 7, k + 14, 98, 1, 3);
		world.setBlock(i + 1, j + 7, k + 15, 98, 1, 3);
		world.setBlock(i + 1, j + 7, k + 16, 98, 1, 3);
		world.setBlock(i + 1, j + 7, k + 17, 98, 1, 3);
		world.setBlock(i + 1, j + 7, k + 18, 98, 1, 3);
		world.setBlock(i + 1, j + 7, k + 19, 98, 1, 3);
		world.setBlock(i + 1, j + 7, k + 20, 98, 1, 3);
		world.setBlock(i + 1, j + 7, k + 21, 98, 1, 3);
		world.setBlock(i + 1, j + 7, k + 22, 98, 1, 3);
		world.setBlock(i + 1, j + 7, k + 23, 98, 1, 3);
		world.setBlock(i + 1, j + 7, k + 24, 98, 1, 3);
		world.setBlock(i + 1, j + 7, k + 25, 98, 1, 3);
		world.setBlock(i + 1, j + 7, k + 26, 98, 1, 3);
		world.setBlock(i + 1, j + 7, k + 27, 98, 1, 3);
		world.setBlock(i + 1, j + 7, k + 28, 98, 1, 3);
		world.setBlock(i + 1, j + 7, k + 29, 98, 1, 3);
		world.setBlock(i + 1, j + 7, k + 30, 98, 1, 3);
		world.setBlock(i + 1, j + 7, k + 31, 98, 1, 3);
		world.setBlock(i + 1, j + 7, k + 32, 98, 1, 3);
		world.setBlock(i + 1, j + 7, k + 33, 98, 1, 3);
		world.setBlock(i + 1, j + 7, k + 34, 98, 3, 3);
		world.setBlock(i + 1, j + 13, k + 0, 109, 2, 3);
		world.setBlock(i + 1, j + 13, k + 1, 98, 1, 3);
		world.setBlock(i + 1, j + 13, k + 2, 98, 1, 3);
		world.setBlock(i + 1, j + 13, k + 3, 98, 2, 3);
		world.setBlock(i + 1, j + 13, k + 4, 89, 0, 4);
		world.setBlock(i + 1, j + 13, k + 13, 89, 0, 4);
		world.setBlock(i + 1, j + 13, k + 21, 89, 0, 4);
		world.setBlock(i + 1, j + 13, k + 29, 89, 0, 4);
		world.setBlock(i + 1, j + 13, k + 34, 109, 3, 3);
		world.setBlock(i + 1, j + 14, k + 1, 44, 5, 3);
		world.setBlock(i + 1, j + 14, k + 2, 44, 5, 3);
		world.setBlock(i + 1, j + 14, k + 3, 44, 5, 3);
		world.setBlock(i + 1, j + 14, k + 4, 44, 5, 3);
		world.setBlock(i + 1, j + 14, k + 5, 44, 5, 3);
		world.setBlock(i + 1, j + 14, k + 6, 44, 5, 3);
		world.setBlock(i + 1, j + 14, k + 7, 44, 5, 3);
		world.setBlock(i + 1, j + 14, k + 8, 44, 5, 3);
		world.setBlock(i + 1, j + 14, k + 9, 44, 5, 3);
		world.setBlock(i + 1, j + 14, k + 10, 44, 5, 3);
		world.setBlock(i + 1, j + 14, k + 11, 44, 5, 3);
		world.setBlock(i + 1, j + 14, k + 12, 44, 5, 3);
		world.setBlock(i + 1, j + 14, k + 13, 44, 5, 3);
		world.setBlock(i + 1, j + 14, k + 14, 44, 5, 3);
		world.setBlock(i + 1, j + 14, k + 15, 44, 5, 3);
		world.setBlock(i + 1, j + 14, k + 16, 44, 5, 3);
		world.setBlock(i + 1, j + 14, k + 17, 44, 5, 3);
		world.setBlock(i + 1, j + 14, k + 18, 44, 5, 3);
		world.setBlock(i + 1, j + 14, k + 19, 44, 5, 3);
		world.setBlock(i + 1, j + 14, k + 20, 44, 5, 3);
		world.setBlock(i + 1, j + 14, k + 21, 44, 5, 3);
		world.setBlock(i + 1, j + 14, k + 22, 44, 5, 3);
		world.setBlock(i + 1, j + 14, k + 23, 44, 5, 3);
		world.setBlock(i + 1, j + 14, k + 24, 44, 5, 3);
		world.setBlock(i + 1, j + 14, k + 25, 44, 5, 3);
		world.setBlock(i + 1, j + 14, k + 26, 44, 5, 3);
		world.setBlock(i + 1, j + 14, k + 27, 44, 5, 3);
		world.setBlock(i + 1, j + 14, k + 28, 44, 5, 3);
		world.setBlock(i + 1, j + 14, k + 29, 44, 5, 3);
		world.setBlock(i + 1, j + 14, k + 30, 44, 5, 3);
		world.setBlock(i + 1, j + 14, k + 31, 44, 5, 3);
		world.setBlock(i + 1, j + 14, k + 32, 44, 5, 3);
		world.setBlock(i + 1, j + 14, k + 33, 44, 5, 3);
		world.setBlock(i + 2, j + 0, k + 0, 98, 0, 4);
		world.setBlock(i + 2, j + 0, k + 1, 98, 1, 3);
		world.setBlock(i + 2, j + 0, k + 2, 98, 1, 3);
		world.setBlock(i + 2, j + 0, k + 3, 98, 2, 3);
		world.setBlock(i + 2, j + 0, k + 4, 98, 1, 3);
		world.setBlock(i + 2, j + 0, k + 5, 98, 1, 3);
		world.setBlock(i + 2, j + 0, k + 6, 98, 1, 3);
		world.setBlock(i + 2, j + 0, k + 7, 98, 1, 3);
		world.setBlock(i + 2, j + 0, k + 8, 98, 1, 3);
		world.setBlock(i + 2, j + 0, k + 9, 98, 1, 3);
		world.setBlock(i + 2, j + 0, k + 10, 98, 1, 3);
		world.setBlock(i + 2, j + 0, k + 11, 98, 1, 3);
		world.setBlock(i + 2, j + 0, k + 12, 98, 1, 3);
		world.setBlock(i + 2, j + 0, k + 13, 98, 1, 3);
		world.setBlock(i + 2, j + 0, k + 14, 98, 1, 3);
		world.setBlock(i + 2, j + 0, k + 15, 98, 1, 3);
		world.setBlock(i + 2, j + 0, k + 16, 98, 1, 3);
		world.setBlock(i + 2, j + 0, k + 17, 98, 1, 3);
		world.setBlock(i + 2, j + 0, k + 18, 98, 1, 3);
		world.setBlock(i + 2, j + 0, k + 19, 98, 1, 3);
		world.setBlock(i + 2, j + 0, k + 20, 98, 1, 3);
		world.setBlock(i + 2, j + 0, k + 21, 98, 1, 3);
		world.setBlock(i + 2, j + 0, k + 22, 98, 1, 3);
		world.setBlock(i + 2, j + 0, k + 23, 98, 1, 3);
		world.setBlock(i + 2, j + 0, k + 24, 98, 1, 3);
		world.setBlock(i + 2, j + 0, k + 25, 98, 1, 3);
		world.setBlock(i + 2, j + 0, k + 26, 98, 1, 3);
		world.setBlock(i + 2, j + 0, k + 27, 98, 1, 3);
		world.setBlock(i + 2, j + 0, k + 28, 98, 1, 3);
		world.setBlock(i + 2, j + 0, k + 29, 98, 1, 3);
		world.setBlock(i + 2, j + 0, k + 30, 98, 1, 3);
		world.setBlock(i + 2, j + 0, k + 31, 98, 1, 3);
		world.setBlock(i + 2, j + 0, k + 32, 98, 1, 3);
		world.setBlock(i + 2, j + 0, k + 33, 98, 1, 3);
		world.setBlock(i + 2, j + 0, k + 34, 98, 0, 4);
		world.setBlock(i + 2, j + 7, k + 0, 98, 3, 3);
		world.setBlock(i + 2, j + 7, k + 1, 98, 1, 3);
		world.setBlock(i + 2, j + 7, k + 2, 98, 1, 3);
		world.setBlock(i + 2, j + 7, k + 3, 98, 2, 3);
		world.setBlock(i + 2, j + 7, k + 4, 98, 1, 3);
		world.setBlock(i + 2, j + 7, k + 5, 98, 1, 3);
		world.setBlock(i + 2, j + 7, k + 6, 98, 1, 3);
		world.setBlock(i + 2, j + 7, k + 7, 98, 1, 3);
		world.setBlock(i + 2, j + 7, k + 8, 98, 1, 3);
		world.setBlock(i + 2, j + 7, k + 9, 98, 1, 3);
		world.setBlock(i + 2, j + 7, k + 10, 98, 1, 3);
		world.setBlock(i + 2, j + 7, k + 11, 98, 1, 3);
		world.setBlock(i + 2, j + 7, k + 12, 98, 1, 3);
		world.setBlock(i + 2, j + 7, k + 13, 98, 1, 3);
		world.setBlock(i + 2, j + 7, k + 14, 98, 1, 3);
		world.setBlock(i + 2, j + 7, k + 15, 98, 1, 3);
		world.setBlock(i + 2, j + 7, k + 16, 98, 1, 3);
		world.setBlock(i + 2, j + 7, k + 17, 98, 1, 3);
		world.setBlock(i + 2, j + 7, k + 18, 98, 1, 3);
		world.setBlock(i + 2, j + 7, k + 19, 98, 1, 3);
		world.setBlock(i + 2, j + 7, k + 20, 98, 1, 3);
		world.setBlock(i + 2, j + 7, k + 21, 98, 1, 3);
		world.setBlock(i + 2, j + 7, k + 22, 98, 1, 3);
		world.setBlock(i + 2, j + 7, k + 23, 98, 1, 3);
		world.setBlock(i + 2, j + 7, k + 24, 98, 1, 3);
		world.setBlock(i + 2, j + 7, k + 25, 98, 1, 3);
		world.setBlock(i + 2, j + 7, k + 26, 98, 1, 3);
		world.setBlock(i + 2, j + 7, k + 27, 98, 1, 3);
		world.setBlock(i + 2, j + 7, k + 28, 98, 1, 3);
		world.setBlock(i + 2, j + 7, k + 29, 98, 1, 3);
		world.setBlock(i + 2, j + 7, k + 30, 98, 1, 3);
		world.setBlock(i + 2, j + 7, k + 31, 98, 1, 3);
		world.setBlock(i + 2, j + 7, k + 32, 98, 1, 3);
		world.setBlock(i + 2, j + 7, k + 33, 98, 1, 3);
		world.setBlock(i + 2, j + 7, k + 34, 98, 3, 3);
		world.setBlock(i + 2, j + 13, k + 0, 109, 2, 3);
		world.setBlock(i + 2, j + 13, k + 1, 98, 1, 3);
		world.setBlock(i + 2, j + 13, k + 2, 98, 1, 3);
		world.setBlock(i + 2, j + 13, k + 3, 98, 2, 3);
		world.setBlock(i + 2, j + 13, k + 34, 109, 3, 3);
		world.setBlock(i + 2, j + 14, k + 1, 44, 5, 3);
		world.setBlock(i + 2, j + 14, k + 2, 44, 5, 3);
		world.setBlock(i + 2, j + 14, k + 3, 44, 5, 3);
		world.setBlock(i + 2, j + 14, k + 4, 44, 5, 3);
		world.setBlock(i + 2, j + 14, k + 5, 44, 5, 3);
		world.setBlock(i + 2, j + 14, k + 6, 44, 5, 3);
		world.setBlock(i + 2, j + 14, k + 7, 44, 5, 3);
		world.setBlock(i + 2, j + 14, k + 8, 44, 5, 3);
		world.setBlock(i + 2, j + 14, k + 9, 44, 5, 3);
		world.setBlock(i + 2, j + 14, k + 10, 44, 5, 3);
		world.setBlock(i + 2, j + 14, k + 11, 44, 5, 3);
		world.setBlock(i + 2, j + 14, k + 12, 44, 5, 3);
		world.setBlock(i + 2, j + 14, k + 13, 44, 5, 3);
		world.setBlock(i + 2, j + 14, k + 14, 44, 5, 3);
		world.setBlock(i + 2, j + 14, k + 15, 44, 5, 3);
		world.setBlock(i + 2, j + 14, k + 16, 44, 5, 3);
		world.setBlock(i + 2, j + 14, k + 17, 44, 5, 3);
		world.setBlock(i + 2, j + 14, k + 18, 44, 5, 3);
		world.setBlock(i + 2, j + 14, k + 19, 44, 5, 3);
		world.setBlock(i + 2, j + 14, k + 20, 44, 5, 3);
		world.setBlock(i + 2, j + 14, k + 21, 44, 5, 3);
		world.setBlock(i + 2, j + 14, k + 22, 44, 5, 3);
		world.setBlock(i + 2, j + 14, k + 23, 44, 5, 3);
		world.setBlock(i + 2, j + 14, k + 24, 44, 5, 3);
		world.setBlock(i + 2, j + 14, k + 25, 44, 5, 3);
		world.setBlock(i + 2, j + 14, k + 26, 44, 5, 3);
		world.setBlock(i + 2, j + 14, k + 27, 44, 5, 3);
		world.setBlock(i + 2, j + 14, k + 28, 44, 5, 3);
		world.setBlock(i + 2, j + 14, k + 29, 44, 5, 3);
		world.setBlock(i + 2, j + 14, k + 30, 44, 5, 3);
		world.setBlock(i + 2, j + 14, k + 31, 44, 5, 3);
		world.setBlock(i + 2, j + 14, k + 32, 44, 5, 3);
		world.setBlock(i + 2, j + 14, k + 33, 44, 5, 3);
		world.setBlock(i + 3, j + 0, k + 0, 98, 0, 4);
		world.setBlock(i + 3, j + 0, k + 1, 98, 1, 3);
		world.setBlock(i + 3, j + 0, k + 2, 98, 1, 3);
		world.setBlock(i + 3, j + 0, k + 3, 98, 2, 3);
		world.setBlock(i + 3, j + 0, k + 4, 98, 2, 3);
		world.setBlock(i + 3, j + 0, k + 5, 98, 2, 3);
		world.setBlock(i + 3, j + 0, k + 6, 98, 2, 3);
		world.setBlock(i + 3, j + 0, k + 7, 98, 2, 3);
		world.setBlock(i + 3, j + 0, k + 8, 98, 2, 3);
		world.setBlock(i + 3, j + 0, k + 9, 98, 2, 3);
		world.setBlock(i + 3, j + 0, k + 10, 98, 2, 3);
		world.setBlock(i + 3, j + 0, k + 11, 98, 2, 3);
		world.setBlock(i + 3, j + 0, k + 12, 98, 2, 3);
		world.setBlock(i + 3, j + 0, k + 13, 98, 2, 3);
		world.setBlock(i + 3, j + 0, k + 14, 98, 2, 3);
		world.setBlock(i + 3, j + 0, k + 15, 98, 2, 3);
		world.setBlock(i + 3, j + 0, k + 16, 98, 2, 3);
		world.setBlock(i + 3, j + 0, k + 17, 98, 2, 3);
		world.setBlock(i + 3, j + 0, k + 18, 98, 2, 3);
		world.setBlock(i + 3, j + 0, k + 19, 98, 2, 3);
		world.setBlock(i + 3, j + 0, k + 20, 98, 2, 3);
		world.setBlock(i + 3, j + 0, k + 21, 98, 2, 3);
		world.setBlock(i + 3, j + 0, k + 22, 98, 2, 3);
		world.setBlock(i + 3, j + 0, k + 23, 98, 2, 3);
		world.setBlock(i + 3, j + 0, k + 24, 98, 2, 3);
		world.setBlock(i + 3, j + 0, k + 25, 98, 2, 3);
		world.setBlock(i + 3, j + 0, k + 26, 98, 2, 3);
		world.setBlock(i + 3, j + 0, k + 27, 98, 2, 3);
		world.setBlock(i + 3, j + 0, k + 28, 98, 2, 3);
		world.setBlock(i + 3, j + 0, k + 29, 98, 2, 3);
		world.setBlock(i + 3, j + 0, k + 30, 98, 2, 3);
		world.setBlock(i + 3, j + 0, k + 31, 98, 2, 3);
		world.setBlock(i + 3, j + 0, k + 32, 98, 2, 3);
		world.setBlock(i + 3, j + 0, k + 33, 98, 2, 3);
		world.setBlock(i + 3, j + 0, k + 34, 98, 2, 3);
		world.setBlock(i + 3, j + 1, k + 3, 98, 2, 3);
		world.setBlock(i + 3, j + 1, k + 4, 98, 2, 3);
		world.setBlock(i + 3, j + 1, k + 5, 98, 2, 3);
		world.setBlock(i + 3, j + 1, k + 6, 98, 2, 3);
		world.setBlock(i + 3, j + 1, k + 7, 98, 2, 3);
		world.setBlock(i + 3, j + 1, k + 8, 98, 2, 3);
		world.setBlock(i + 3, j + 1, k + 9, 98, 2, 3);
		world.setBlock(i + 3, j + 1, k + 10, 98, 2, 3);
		world.setBlock(i + 3, j + 1, k + 11, 98, 2, 3);
		world.setBlock(i + 3, j + 1, k + 12, 98, 2, 3);
		world.setBlock(i + 3, j + 1, k + 13, 98, 2, 3);
		world.setBlock(i + 3, j + 1, k + 14, 98, 2, 3);
		world.setBlock(i + 3, j + 1, k + 15, 98, 2, 3);
		world.setBlock(i + 3, j + 1, k + 16, 98, 2, 3);
		world.setBlock(i + 3, j + 1, k + 17, 98, 2, 3);
		world.setBlock(i + 3, j + 1, k + 18, 98, 2, 3);
		world.setBlock(i + 3, j + 1, k + 19, 98, 2, 3);
		world.setBlock(i + 3, j + 1, k + 20, 98, 2, 3);
		world.setBlock(i + 3, j + 1, k + 21, 98, 2, 3);
		world.setBlock(i + 3, j + 1, k + 22, 98, 2, 3);
		world.setBlock(i + 3, j + 1, k + 23, 98, 2, 3);
		world.setBlock(i + 3, j + 1, k + 24, 98, 2, 3);
		world.setBlock(i + 3, j + 1, k + 25, 98, 2, 3);
		world.setBlock(i + 3, j + 1, k + 26, 98, 2, 3);
		world.setBlock(i + 3, j + 1, k + 27, 98, 2, 3);
		world.setBlock(i + 3, j + 1, k + 28, 98, 2, 3);
		world.setBlock(i + 3, j + 1, k + 29, 98, 2, 3);
		world.setBlock(i + 3, j + 1, k + 30, 98, 2, 3);
		world.setBlock(i + 3, j + 1, k + 31, 98, 2, 3);
		world.setBlock(i + 3, j + 2, k + 3, 98, 2, 3);
		world.setBlock(i + 3, j + 2, k + 4, 98, 2, 3);
		world.setBlock(i + 3, j + 2, k + 5, 98, 2, 3);
		world.setBlock(i + 3, j + 2, k + 6, 98, 2, 3);
		world.setBlock(i + 3, j + 2, k + 7, 98, 2, 3);
		world.setBlock(i + 3, j + 2, k + 8, 98, 2, 3);
		world.setBlock(i + 3, j + 2, k + 9, 98, 2, 3);
		world.setBlock(i + 3, j + 2, k + 10, 98, 2, 3);
		world.setBlock(i + 3, j + 2, k + 11, 98, 2, 3);
		world.setBlock(i + 3, j + 2, k + 12, 98, 2, 3);
		world.setBlock(i + 3, j + 2, k + 13, 98, 2, 3);
		world.setBlock(i + 3, j + 2, k + 14, 98, 2, 3);
		world.setBlock(i + 3, j + 2, k + 15, 98, 2, 3);
		world.setBlock(i + 3, j + 2, k + 16, 98, 2, 3);
		world.setBlock(i + 3, j + 2, k + 17, 98, 2, 3);
		world.setBlock(i + 3, j + 2, k + 18, 98, 2, 3);
		world.setBlock(i + 3, j + 2, k + 19, 98, 2, 3);
		world.setBlock(i + 3, j + 2, k + 20, 98, 2, 3);
		world.setBlock(i + 3, j + 2, k + 21, 98, 2, 3);
		world.setBlock(i + 3, j + 2, k + 22, 98, 2, 3);
		world.setBlock(i + 3, j + 2, k + 23, 98, 2, 3);
		world.setBlock(i + 3, j + 2, k + 24, 98, 2, 3);
		world.setBlock(i + 3, j + 2, k + 25, 101, 0, 4);
		world.setBlock(i + 3, j + 2, k + 26, 98, 2, 3);
		world.setBlock(i + 3, j + 2, k + 27, 98, 2, 3);
		world.setBlock(i + 3, j + 2, k + 28, 98, 2, 3);
		world.setBlock(i + 3, j + 2, k + 29, 98, 2, 3);
		world.setBlock(i + 3, j + 2, k + 30, 98, 2, 3);
		world.setBlock(i + 3, j + 2, k + 31, 101, 0, 4);
		world.setBlock(i + 3, j + 3, k + 3, 98, 2, 3);
		world.setBlock(i + 3, j + 3, k + 4, 98, 2, 3);
		world.setBlock(i + 3, j + 3, k + 5, 98, 2, 3);
		world.setBlock(i + 3, j + 3, k + 6, 98, 2, 3);
		world.setBlock(i + 3, j + 3, k + 7, 98, 2, 3);
		world.setBlock(i + 3, j + 3, k + 8, 98, 2, 3);
		world.setBlock(i + 3, j + 3, k + 9, 101, 0, 4);
		world.setBlock(i + 3, j + 3, k + 10, 98, 2, 3);
		world.setBlock(i + 3, j + 3, k + 11, 98, 2, 3);
		world.setBlock(i + 3, j + 3, k + 12, 98, 2, 3);
		world.setBlock(i + 3, j + 3, k + 13, 98, 2, 3);
		world.setBlock(i + 3, j + 3, k + 14, 98, 2, 3);
		world.setBlock(i + 3, j + 3, k + 15, 98, 2, 3);
		world.setBlock(i + 3, j + 3, k + 16, 98, 2, 3);
		world.setBlock(i + 3, j + 3, k + 17, 98, 2, 3);
		world.setBlock(i + 3, j + 3, k + 18, 98, 2, 3);
		world.setBlock(i + 3, j + 3, k + 19, 98, 2, 3);
		world.setBlock(i + 3, j + 3, k + 20, 98, 2, 3);
		world.setBlock(i + 3, j + 3, k + 21, 101, 0, 4);
		world.setBlock(i + 3, j + 3, k + 22, 98, 2, 3);
		world.setBlock(i + 3, j + 3, k + 23, 98, 2, 3);
		world.setBlock(i + 3, j + 3, k + 24, 98, 2, 3);
		world.setBlock(i + 3, j + 3, k + 25, 98, 2, 3);
		world.setBlock(i + 3, j + 3, k + 26, 98, 2, 3);
		world.setBlock(i + 3, j + 3, k + 27, 98, 2, 3);
		world.setBlock(i + 3, j + 3, k + 28, 98, 2, 3);
		world.setBlock(i + 3, j + 3, k + 29, 98, 2, 3);
		world.setBlock(i + 3, j + 3, k + 30, 98, 2, 3);
		world.setBlock(i + 3, j + 3, k + 31, 98, 2, 3);
		world.setBlock(i + 3, j + 4, k + 3, 98, 2, 3);
		world.setBlock(i + 3, j + 4, k + 4, 98, 2, 3);
		world.setBlock(i + 3, j + 4, k + 5, 98, 2, 3);
		world.setBlock(i + 3, j + 4, k + 6, 98, 2, 3);
		world.setBlock(i + 3, j + 4, k + 7, 98, 2, 3);
		world.setBlock(i + 3, j + 4, k + 8, 98, 2, 3);
		world.setBlock(i + 3, j + 4, k + 9, 98, 2, 3);
		world.setBlock(i + 3, j + 4, k + 10, 98, 2, 3);
		world.setBlock(i + 3, j + 4, k + 11, 98, 2, 3);
		world.setBlock(i + 3, j + 4, k + 12, 98, 2, 3);
		world.setBlock(i + 3, j + 4, k + 13, 98, 2, 3);
		world.setBlock(i + 3, j + 4, k + 14, 98, 2, 3);
		world.setBlock(i + 3, j + 4, k + 15, 98, 2, 3);
		world.setBlock(i + 3, j + 4, k + 16, 101, 0, 4);
		world.setBlock(i + 3, j + 4, k + 17, 98, 2, 3);
		world.setBlock(i + 3, j + 4, k + 18, 98, 2, 3);
		world.setBlock(i + 3, j + 4, k + 19, 98, 2, 3);
		world.setBlock(i + 3, j + 4, k + 20, 98, 2, 3);
		world.setBlock(i + 3, j + 4, k + 21, 98, 2, 3);
		world.setBlock(i + 3, j + 4, k + 22, 98, 2, 3);
		world.setBlock(i + 3, j + 4, k + 23, 98, 2, 3);
		world.setBlock(i + 3, j + 4, k + 24, 98, 2, 3);
		world.setBlock(i + 3, j + 4, k + 25, 98, 2, 3);
		world.setBlock(i + 3, j + 4, k + 26, 98, 2, 3);
		world.setBlock(i + 3, j + 4, k + 27, 98, 2, 3);
		world.setBlock(i + 3, j + 4, k + 28, 101, 0, 4);
		world.setBlock(i + 3, j + 4, k + 29, 98, 2, 3);
		world.setBlock(i + 3, j + 4, k + 30, 98, 2, 3);
		world.setBlock(i + 3, j + 4, k + 31, 98, 2, 3);
		world.setBlock(i + 3, j + 5, k + 3, 98, 2, 3);
		world.setBlock(i + 3, j + 5, k + 4, 98, 2, 3);
		world.setBlock(i + 3, j + 5, k + 5, 98, 2, 3);
		world.setBlock(i + 3, j + 5, k + 6, 98, 2, 3);
		world.setBlock(i + 3, j + 5, k + 7, 98, 2, 3);
		world.setBlock(i + 3, j + 5, k + 8, 98, 2, 3);
		world.setBlock(i + 3, j + 5, k + 9, 98, 2, 3);
		world.setBlock(i + 3, j + 5, k + 10, 98, 2, 3);
		world.setBlock(i + 3, j + 5, k + 11, 98, 2, 3);
		world.setBlock(i + 3, j + 5, k + 12, 98, 2, 3);
		world.setBlock(i + 3, j + 5, k + 13, 98, 2, 3);
		world.setBlock(i + 3, j + 5, k + 14, 98, 2, 3);
		world.setBlock(i + 3, j + 5, k + 15, 98, 2, 3);
		world.setBlock(i + 3, j + 5, k + 16, 98, 2, 3);
		world.setBlock(i + 3, j + 5, k + 17, 98, 2, 3);
		world.setBlock(i + 3, j + 5, k + 18, 98, 2, 3);
		world.setBlock(i + 3, j + 5, k + 19, 98, 2, 3);
		world.setBlock(i + 3, j + 5, k + 20, 98, 2, 3);
		world.setBlock(i + 3, j + 5, k + 21, 98, 2, 3);
		world.setBlock(i + 3, j + 5, k + 22, 98, 2, 3);
		world.setBlock(i + 3, j + 5, k + 23, 98, 2, 3);
		world.setBlock(i + 3, j + 5, k + 24, 98, 2, 3);
		world.setBlock(i + 3, j + 5, k + 25, 98, 2, 3);
		world.setBlock(i + 3, j + 5, k + 26, 98, 2, 3);
		world.setBlock(i + 3, j + 5, k + 27, 98, 2, 3);
		world.setBlock(i + 3, j + 5, k + 28, 98, 2, 3);
		world.setBlock(i + 3, j + 5, k + 29, 98, 2, 3);
		world.setBlock(i + 3, j + 5, k + 30, 98, 2, 3);
		world.setBlock(i + 3, j + 5, k + 31, 98, 2, 3);
		world.setBlock(i + 3, j + 6, k + 3, 98, 2, 3);
		world.setBlock(i + 3, j + 6, k + 4, 98, 2, 3);
		world.setBlock(i + 3, j + 6, k + 5, 98, 2, 3);
		world.setBlock(i + 3, j + 6, k + 6, 98, 2, 3);
		world.setBlock(i + 3, j + 6, k + 7, 98, 2, 3);
		world.setBlock(i + 3, j + 6, k + 8, 98, 2, 3);
		world.setBlock(i + 3, j + 6, k + 9, 98, 2, 3);
		world.setBlock(i + 3, j + 6, k + 10, 98, 2, 3);
		world.setBlock(i + 3, j + 6, k + 11, 98, 2, 3);
		world.setBlock(i + 3, j + 6, k + 12, 98, 2, 3);
		world.setBlock(i + 3, j + 6, k + 13, 98, 2, 3);
		world.setBlock(i + 3, j + 6, k + 14, 98, 2, 3);
		world.setBlock(i + 3, j + 6, k + 15, 98, 2, 3);
		world.setBlock(i + 3, j + 6, k + 16, 98, 2, 3);
		world.setBlock(i + 3, j + 6, k + 17, 98, 2, 3);
		world.setBlock(i + 3, j + 6, k + 18, 98, 2, 3);
		world.setBlock(i + 3, j + 6, k + 19, 98, 2, 3);
		world.setBlock(i + 3, j + 6, k + 20, 98, 2, 3);
		world.setBlock(i + 3, j + 6, k + 21, 98, 2, 3);
		world.setBlock(i + 3, j + 6, k + 22, 98, 2, 3);
		world.setBlock(i + 3, j + 6, k + 23, 98, 2, 3);
		world.setBlock(i + 3, j + 6, k + 24, 98, 2, 3);
		world.setBlock(i + 3, j + 6, k + 25, 98, 2, 3);
		world.setBlock(i + 3, j + 6, k + 26, 98, 2, 3);
		world.setBlock(i + 3, j + 6, k + 27, 98, 2, 3);
		world.setBlock(i + 3, j + 6, k + 28, 98, 2, 3);
		world.setBlock(i + 3, j + 6, k + 29, 98, 2, 3);
		world.setBlock(i + 3, j + 6, k + 30, 98, 2, 3);
		world.setBlock(i + 3, j + 6, k + 31, 98, 2, 3);
		world.setBlock(i + 3, j + 7, k + 0, 98, 3, 3);
		world.setBlock(i + 3, j + 7, k + 1, 98, 1, 3);
		world.setBlock(i + 3, j + 7, k + 2, 98, 1, 3);
		world.setBlock(i + 3, j + 7, k + 3, 98, 2, 3);
		world.setBlock(i + 3, j + 7, k + 4, 98, 1, 3);
		world.setBlock(i + 3, j + 7, k + 5, 98, 1, 3);
		world.setBlock(i + 3, j + 7, k + 6, 98, 1, 3);
		world.setBlock(i + 3, j + 7, k + 7, 98, 1, 3);
		world.setBlock(i + 3, j + 7, k + 8, 98, 1, 3);
		world.setBlock(i + 3, j + 7, k + 9, 98, 1, 3);
		world.setBlock(i + 3, j + 7, k + 10, 98, 1, 3);
		world.setBlock(i + 3, j + 7, k + 11, 98, 1, 3);
		world.setBlock(i + 3, j + 7, k + 12, 98, 1, 3);
		world.setBlock(i + 3, j + 7, k + 13, 98, 1, 3);
		world.setBlock(i + 3, j + 7, k + 14, 98, 1, 3);
		world.setBlock(i + 3, j + 7, k + 15, 98, 1, 3);
		world.setBlock(i + 3, j + 7, k + 16, 98, 1, 3);
		world.setBlock(i + 3, j + 7, k + 17, 98, 1, 3);
		world.setBlock(i + 3, j + 7, k + 18, 98, 1, 3);
		world.setBlock(i + 3, j + 7, k + 19, 98, 1, 3);
		world.setBlock(i + 3, j + 7, k + 20, 98, 1, 3);
		world.setBlock(i + 3, j + 7, k + 21, 98, 1, 3);
		world.setBlock(i + 3, j + 7, k + 22, 98, 1, 3);
		world.setBlock(i + 3, j + 7, k + 23, 98, 1, 3);
		world.setBlock(i + 3, j + 7, k + 24, 98, 1, 3);
		world.setBlock(i + 3, j + 7, k + 25, 98, 1, 3);
		world.setBlock(i + 3, j + 7, k + 26, 98, 1, 3);
		world.setBlock(i + 3, j + 7, k + 27, 98, 1, 3);
		world.setBlock(i + 3, j + 7, k + 28, 98, 1, 3);
		world.setBlock(i + 3, j + 7, k + 29, 98, 1, 3);
		world.setBlock(i + 3, j + 7, k + 30, 98, 1, 3);
		world.setBlock(i + 3, j + 7, k + 31, 98, 1, 3);
		world.setBlock(i + 3, j + 7, k + 32, 98, 1, 3);
		world.setBlock(i + 3, j + 7, k + 33, 98, 1, 3);
		world.setBlock(i + 3, j + 7, k + 34, 98, 3, 3);
		world.setBlock(i + 3, j + 8, k + 3, 98, 2, 3);
		world.setBlock(i + 3, j + 8, k + 4, 98, 2, 3);
		world.setBlock(i + 3, j + 8, k + 5, 98, 2, 3);
		world.setBlock(i + 3, j + 8, k + 6, 98, 2, 3);
		world.setBlock(i + 3, j + 8, k + 7, 98, 2, 3);
		world.setBlock(i + 3, j + 8, k + 8, 98, 2, 3);
		world.setBlock(i + 3, j + 8, k + 9, 98, 2, 3);
		world.setBlock(i + 3, j + 8, k + 10, 98, 2, 3);
		world.setBlock(i + 3, j + 8, k + 11, 98, 2, 3);
		world.setBlock(i + 3, j + 8, k + 12, 98, 2, 3);
		world.setBlock(i + 3, j + 8, k + 13, 98, 2, 3);
		world.setBlock(i + 3, j + 8, k + 14, 98, 2, 3);
		world.setBlock(i + 3, j + 8, k + 15, 98, 2, 3);
		world.setBlock(i + 3, j + 8, k + 16, 98, 2, 3);
		world.setBlock(i + 3, j + 8, k + 17, 98, 2, 3);
		world.setBlock(i + 3, j + 8, k + 18, 98, 2, 3);
		world.setBlock(i + 3, j + 8, k + 19, 98, 2, 3);
		world.setBlock(i + 3, j + 8, k + 20, 98, 2, 3);
		world.setBlock(i + 3, j + 8, k + 21, 98, 2, 3);
		world.setBlock(i + 3, j + 8, k + 22, 98, 2, 3);
		world.setBlock(i + 3, j + 8, k + 23, 98, 2, 3);
		world.setBlock(i + 3, j + 8, k + 24, 98, 2, 3);
		world.setBlock(i + 3, j + 8, k + 25, 98, 2, 3);
		world.setBlock(i + 3, j + 8, k + 26, 98, 2, 3);
		world.setBlock(i + 3, j + 8, k + 27, 98, 2, 3);
		world.setBlock(i + 3, j + 8, k + 28, 98, 2, 3);
		world.setBlock(i + 3, j + 8, k + 29, 98, 2, 3);
		world.setBlock(i + 3, j + 8, k + 30, 98, 2, 3);
		world.setBlock(i + 3, j + 8, k + 31, 98, 2, 3);
		world.setBlock(i + 3, j + 9, k + 3, 98, 2, 3);
		world.setBlock(i + 3, j + 9, k + 4, 98, 2, 3);
		world.setBlock(i + 3, j + 9, k + 5, 98, 2, 3);
		world.setBlock(i + 3, j + 9, k + 6, 98, 2, 3);
		world.setBlock(i + 3, j + 9, k + 7, 98, 2, 3);
		world.setBlock(i + 3, j + 9, k + 8, 98, 2, 3);
		world.setBlock(i + 3, j + 9, k + 9, 98, 2, 3);
		world.setBlock(i + 3, j + 9, k + 10, 98, 2, 3);
		world.setBlock(i + 3, j + 9, k + 11, 98, 2, 3);
		world.setBlock(i + 3, j + 9, k + 12, 98, 2, 3);
		world.setBlock(i + 3, j + 9, k + 13, 98, 2, 3);
		world.setBlock(i + 3, j + 9, k + 14, 98, 2, 3);
		world.setBlock(i + 3, j + 9, k + 15, 98, 2, 3);
		world.setBlock(i + 3, j + 9, k + 16, 98, 2, 3);
		world.setBlock(i + 3, j + 9, k + 17, 98, 2, 3);
		world.setBlock(i + 3, j + 9, k + 18, 98, 2, 3);
		world.setBlock(i + 3, j + 9, k + 19, 98, 2, 3);
		world.setBlock(i + 3, j + 9, k + 20, 98, 2, 3);
		world.setBlock(i + 3, j + 9, k + 21, 98, 2, 3);
		world.setBlock(i + 3, j + 9, k + 22, 98, 2, 3);
		world.setBlock(i + 3, j + 9, k + 23, 98, 2, 3);
		world.setBlock(i + 3, j + 9, k + 24, 98, 2, 3);
		world.setBlock(i + 3, j + 9, k + 25, 98, 2, 3);
		world.setBlock(i + 3, j + 9, k + 26, 98, 2, 3);
		world.setBlock(i + 3, j + 9, k + 27, 98, 2, 3);
		world.setBlock(i + 3, j + 9, k + 28, 98, 2, 3);
		world.setBlock(i + 3, j + 9, k + 29, 98, 2, 3);
		world.setBlock(i + 3, j + 9, k + 30, 98, 2, 3);
		world.setBlock(i + 3, j + 9, k + 31, 98, 2, 3);
		world.setBlock(i + 3, j + 10, k + 3, 98, 2, 3);
		world.setBlock(i + 3, j + 10, k + 4, 98, 2, 3);
		world.setBlock(i + 3, j + 10, k + 5, 98, 2, 3);
		world.setBlock(i + 3, j + 10, k + 6, 98, 2, 3);
		world.setBlock(i + 3, j + 10, k + 7, 98, 2, 3);
		world.setBlock(i + 3, j + 10, k + 8, 98, 2, 3);
		world.setBlock(i + 3, j + 10, k + 9, 98, 2, 3);
		world.setBlock(i + 3, j + 10, k + 10, 98, 2, 3);
		world.setBlock(i + 3, j + 10, k + 11, 98, 2, 3);
		world.setBlock(i + 3, j + 10, k + 12, 98, 2, 3);
		world.setBlock(i + 3, j + 10, k + 13, 98, 2, 3);
		world.setBlock(i + 3, j + 10, k + 14, 98, 2, 3);
		world.setBlock(i + 3, j + 10, k + 15, 98, 2, 3);
		world.setBlock(i + 3, j + 10, k + 16, 98, 2, 3);
		world.setBlock(i + 3, j + 10, k + 17, 98, 2, 3);
		world.setBlock(i + 3, j + 10, k + 18, 98, 2, 3);
		world.setBlock(i + 3, j + 10, k + 19, 98, 2, 3);
		world.setBlock(i + 3, j + 10, k + 20, 98, 2, 3);
		world.setBlock(i + 3, j + 10, k + 21, 98, 2, 3);
		world.setBlock(i + 3, j + 10, k + 22, 101, 0, 4);
		world.setBlock(i + 3, j + 10, k + 23, 98, 2, 3);
		world.setBlock(i + 3, j + 10, k + 24, 98, 2, 3);
		world.setBlock(i + 3, j + 10, k + 25, 98, 2, 3);
		world.setBlock(i + 3, j + 10, k + 26, 98, 2, 3);
		world.setBlock(i + 3, j + 10, k + 27, 98, 2, 3);
		world.setBlock(i + 3, j + 10, k + 28, 98, 2, 3);
		world.setBlock(i + 3, j + 10, k + 29, 101, 0, 4);
		world.setBlock(i + 3, j + 10, k + 30, 98, 2, 3);
		world.setBlock(i + 3, j + 10, k + 31, 98, 2, 3);
		world.setBlock(i + 3, j + 11, k + 3, 98, 2, 3);
		world.setBlock(i + 3, j + 11, k + 4, 98, 2, 3);
		world.setBlock(i + 3, j + 11, k + 5, 98, 2, 3);
		world.setBlock(i + 3, j + 11, k + 6, 98, 2, 3);
		world.setBlock(i + 3, j + 11, k + 7, 98, 2, 3);
		world.setBlock(i + 3, j + 11, k + 8, 98, 2, 3);
		world.setBlock(i + 3, j + 11, k + 9, 98, 2, 3);
		world.setBlock(i + 3, j + 11, k + 10, 98, 2, 3);
		world.setBlock(i + 3, j + 11, k + 11, 98, 2, 3);
		world.setBlock(i + 3, j + 11, k + 12, 98, 2, 3);
		world.setBlock(i + 3, j + 11, k + 13, 98, 2, 3);
		world.setBlock(i + 3, j + 11, k + 14, 98, 2, 3);
		world.setBlock(i + 3, j + 11, k + 15, 101, 0, 4);
		world.setBlock(i + 3, j + 11, k + 16, 98, 2, 3);
		world.setBlock(i + 3, j + 11, k + 17, 98, 2, 3);
		world.setBlock(i + 3, j + 11, k + 18, 98, 2, 3);
		world.setBlock(i + 3, j + 11, k + 19, 98, 2, 3);
		world.setBlock(i + 3, j + 11, k + 20, 98, 2, 3);
		world.setBlock(i + 3, j + 11, k + 21, 98, 2, 3);
		world.setBlock(i + 3, j + 11, k + 22, 98, 2, 3);
		world.setBlock(i + 3, j + 11, k + 23, 98, 2, 3);
		world.setBlock(i + 3, j + 11, k + 24, 98, 2, 3);
		world.setBlock(i + 3, j + 11, k + 25, 98, 2, 3);
		world.setBlock(i + 3, j + 11, k + 26, 98, 2, 3);
		world.setBlock(i + 3, j + 11, k + 27, 98, 2, 3);
		world.setBlock(i + 3, j + 11, k + 28, 98, 2, 3);
		world.setBlock(i + 3, j + 11, k + 29, 98, 2, 3);
		world.setBlock(i + 3, j + 11, k + 30, 98, 2, 3);
		world.setBlock(i + 3, j + 11, k + 31, 98, 2, 3);
		world.setBlock(i + 3, j + 12, k + 3, 98, 2, 3);
		world.setBlock(i + 3, j + 12, k + 4, 98, 2, 3);
		world.setBlock(i + 3, j + 12, k + 5, 98, 2, 3);
		world.setBlock(i + 3, j + 12, k + 6, 98, 2, 3);
		world.setBlock(i + 3, j + 12, k + 7, 98, 2, 3);
		world.setBlock(i + 3, j + 12, k + 8, 98, 2, 3);
		world.setBlock(i + 3, j + 12, k + 9, 98, 2, 3);
		world.setBlock(i + 3, j + 12, k + 10, 98, 2, 3);
		world.setBlock(i + 3, j + 12, k + 11, 98, 2, 3);
		world.setBlock(i + 3, j + 12, k + 12, 98, 2, 3);
		world.setBlock(i + 3, j + 12, k + 13, 98, 2, 3);
		world.setBlock(i + 3, j + 12, k + 14, 98, 2, 3);
		world.setBlock(i + 3, j + 12, k + 15, 98, 2, 3);
		world.setBlock(i + 3, j + 12, k + 16, 98, 2, 3);
		world.setBlock(i + 3, j + 12, k + 17, 98, 2, 3);
		world.setBlock(i + 3, j + 12, k + 18, 98, 2, 3);
		world.setBlock(i + 3, j + 12, k + 19, 98, 2, 3);
		world.setBlock(i + 3, j + 12, k + 20, 98, 2, 3);
		world.setBlock(i + 3, j + 12, k + 21, 98, 2, 3);
		world.setBlock(i + 3, j + 12, k + 22, 98, 2, 3);
		world.setBlock(i + 3, j + 12, k + 23, 98, 2, 3);
		world.setBlock(i + 3, j + 12, k + 24, 98, 2, 3);
		world.setBlock(i + 3, j + 12, k + 25, 98, 2, 3);
		world.setBlock(i + 3, j + 12, k + 26, 98, 2, 3);
		world.setBlock(i + 3, j + 12, k + 27, 98, 2, 3);
		world.setBlock(i + 3, j + 12, k + 28, 98, 2, 3);
		world.setBlock(i + 3, j + 12, k + 29, 98, 2, 3);
		world.setBlock(i + 3, j + 12, k + 30, 98, 2, 3);
		world.setBlock(i + 3, j + 12, k + 31, 98, 2, 3);
		world.setBlock(i + 3, j + 13, k + 0, 109, 2, 3);
		world.setBlock(i + 3, j + 13, k + 1, 98, 1, 3);
		world.setBlock(i + 3, j + 13, k + 2, 98, 1, 3);
		world.setBlock(i + 3, j + 13, k + 3, 98, 2, 3);
		world.setBlock(i + 3, j + 13, k + 4, 98, 2, 3);
		world.setBlock(i + 3, j + 13, k + 5, 98, 2, 3);
		world.setBlock(i + 3, j + 13, k + 6, 98, 2, 3);
		world.setBlock(i + 3, j + 13, k + 7, 98, 2, 3);
		world.setBlock(i + 3, j + 13, k + 8, 98, 2, 3);
		world.setBlock(i + 3, j + 13, k + 9, 98, 2, 3);
		world.setBlock(i + 3, j + 13, k + 10, 98, 2, 3);
		world.setBlock(i + 3, j + 13, k + 11, 98, 2, 3);
		world.setBlock(i + 3, j + 13, k + 12, 98, 2, 3);
		world.setBlock(i + 3, j + 13, k + 13, 98, 2, 3);
		world.setBlock(i + 3, j + 13, k + 14, 98, 2, 3);
		world.setBlock(i + 3, j + 13, k + 15, 98, 2, 3);
		world.setBlock(i + 3, j + 13, k + 16, 98, 2, 3);
		world.setBlock(i + 3, j + 13, k + 17, 98, 2, 3);
		world.setBlock(i + 3, j + 13, k + 18, 98, 2, 3);
		world.setBlock(i + 3, j + 13, k + 19, 98, 2, 3);
		world.setBlock(i + 3, j + 13, k + 20, 98, 2, 3);
		world.setBlock(i + 3, j + 13, k + 21, 98, 2, 3);
		world.setBlock(i + 3, j + 13, k + 22, 98, 2, 3);
		world.setBlock(i + 3, j + 13, k + 23, 98, 2, 3);
		world.setBlock(i + 3, j + 13, k + 24, 98, 2, 3);
		world.setBlock(i + 3, j + 13, k + 25, 98, 2, 3);
		world.setBlock(i + 3, j + 13, k + 26, 98, 2, 3);
		world.setBlock(i + 3, j + 13, k + 27, 98, 2, 3);
		world.setBlock(i + 3, j + 13, k + 28, 98, 2, 3);
		world.setBlock(i + 3, j + 13, k + 29, 98, 2, 3);
		world.setBlock(i + 3, j + 13, k + 30, 98, 2, 3);
		world.setBlock(i + 3, j + 13, k + 31, 98, 2, 3);
		world.setBlock(i + 3, j + 13, k + 32, 98, 2, 3);
		world.setBlock(i + 3, j + 13, k + 34, 109, 3, 3);
		world.setBlock(i + 3, j + 14, k + 1, 98, 0, 4);
		world.setBlock(i + 3, j + 14, k + 2, 98, 0, 4);
		world.setBlock(i + 3, j + 14, k + 3, 98, 0, 4);
		world.setBlock(i + 3, j + 14, k + 4, 98, 0, 4);
		world.setBlock(i + 3, j + 14, k + 5, 98, 0, 4);
		world.setBlock(i + 3, j + 14, k + 6, 98, 0, 4);
		world.setBlock(i + 3, j + 14, k + 7, 98, 0, 4);
		world.setBlock(i + 3, j + 14, k + 8, 98, 0, 4);
		world.setBlock(i + 3, j + 14, k + 9, 98, 0, 4);
		world.setBlock(i + 3, j + 14, k + 10, 98, 0, 4);
		world.setBlock(i + 3, j + 14, k + 11, 98, 0, 4);
		world.setBlock(i + 3, j + 14, k + 12, 98, 0, 4);
		world.setBlock(i + 3, j + 14, k + 13, 98, 0, 4);
		world.setBlock(i + 3, j + 14, k + 14, 98, 0, 4);
		world.setBlock(i + 3, j + 14, k + 15, 98, 0, 4);
		world.setBlock(i + 3, j + 14, k + 16, 98, 0, 4);
		world.setBlock(i + 3, j + 14, k + 17, 98, 0, 4);
		world.setBlock(i + 3, j + 14, k + 18, 98, 0, 4);
		world.setBlock(i + 3, j + 14, k + 19, 98, 0, 4);
		world.setBlock(i + 3, j + 14, k + 20, 98, 0, 4);
		world.setBlock(i + 3, j + 14, k + 21, 98, 0, 4);
		world.setBlock(i + 3, j + 14, k + 22, 98, 0, 4);
		world.setBlock(i + 3, j + 14, k + 23, 98, 0, 4);
		world.setBlock(i + 3, j + 14, k + 24, 98, 0, 4);
		world.setBlock(i + 3, j + 14, k + 25, 98, 0, 4);
		world.setBlock(i + 3, j + 14, k + 26, 98, 0, 4);
		world.setBlock(i + 3, j + 14, k + 27, 98, 0, 4);
		world.setBlock(i + 3, j + 14, k + 28, 98, 0, 4);
		world.setBlock(i + 3, j + 14, k + 29, 98, 0, 4);
		world.setBlock(i + 3, j + 14, k + 30, 98, 0, 4);
		world.setBlock(i + 3, j + 14, k + 31, 98, 0, 4);
		world.setBlock(i + 3, j + 14, k + 32, 98, 0, 4);
		world.setBlock(i + 3, j + 14, k + 33, 98, 0, 4);
		world.setBlock(i + 4, j + 0, k + 0, 98, 0, 4);
		world.setBlock(i + 4, j + 0, k + 1, 98, 1, 3);
		world.setBlock(i + 4, j + 0, k + 2, 98, 1, 3);
		world.setBlock(i + 4, j + 0, k + 3, 98, 2, 3);
		world.setBlock(i + 4, j + 0, k + 4, 98, 1, 3);
		world.setBlock(i + 4, j + 0, k + 5, 98, 1, 3);
		world.setBlock(i + 4, j + 0, k + 6, 98, 1, 3);
		world.setBlock(i + 4, j + 0, k + 7, 98, 1, 3);
		world.setBlock(i + 4, j + 0, k + 8, 98, 1, 3);
		world.setBlock(i + 4, j + 0, k + 9, 98, 1, 3);
		world.setBlock(i + 4, j + 0, k + 10, 98, 1, 3);
		world.setBlock(i + 4, j + 0, k + 11, 98, 1, 3);
		world.setBlock(i + 4, j + 0, k + 12, 98, 1, 3);
		world.setBlock(i + 4, j + 0, k + 13, 98, 1, 3);
		world.setBlock(i + 4, j + 0, k + 14, 98, 1, 3);
		world.setBlock(i + 4, j + 0, k + 15, 98, 1, 3);
		world.setBlock(i + 4, j + 0, k + 16, 98, 1, 3);
		world.setBlock(i + 4, j + 0, k + 17, 98, 1, 3);
		world.setBlock(i + 4, j + 0, k + 18, 98, 1, 3);
		world.setBlock(i + 4, j + 0, k + 19, 98, 1, 3);
		world.setBlock(i + 4, j + 0, k + 20, 98, 1, 3);
		world.setBlock(i + 4, j + 0, k + 21, 98, 1, 3);
		world.setBlock(i + 4, j + 0, k + 22, 98, 1, 3);
		world.setBlock(i + 4, j + 0, k + 23, 98, 1, 3);
		world.setBlock(i + 4, j + 0, k + 24, 98, 1, 3);
		world.setBlock(i + 4, j + 0, k + 25, 98, 1, 3);
		world.setBlock(i + 4, j + 0, k + 26, 98, 1, 3);
		world.setBlock(i + 4, j + 0, k + 27, 98, 1, 3);
		world.setBlock(i + 4, j + 0, k + 28, 98, 1, 3);
		world.setBlock(i + 4, j + 0, k + 29, 98, 1, 3);
		world.setBlock(i + 4, j + 0, k + 30, 98, 1, 3);
		world.setBlock(i + 4, j + 0, k + 31, 98, 1, 3);
		world.setBlock(i + 4, j + 0, k + 32, 98, 1, 3);
		world.setBlock(i + 4, j + 0, k + 33, 98, 1, 3);
		world.setBlock(i + 4, j + 0, k + 34, 98, 0, 4);
		world.setBlock(i + 4, j + 1, k + 3, 98, 2, 3);
		world.setBlock(i + 4, j + 1, k + 4, 98, 1, 3);
		world.setBlock(i + 4, j + 1, k + 5, 98, 1, 3);
		world.setBlock(i + 4, j + 1, k + 6, 98, 1, 3);
		world.setBlock(i + 4, j + 1, k + 7, 98, 1, 3);
		world.setBlock(i + 4, j + 1, k + 8, 98, 1, 3);
		world.setBlock(i + 4, j + 1, k + 9, 98, 1, 3);
		world.setBlock(i + 4, j + 1, k + 10, 98, 1, 3);
		world.setBlock(i + 4, j + 1, k + 11, 98, 1, 3);
		world.setBlock(i + 4, j + 1, k + 12, 98, 1, 3);
		world.setBlock(i + 4, j + 1, k + 13, 98, 1, 3);
		world.setBlock(i + 4, j + 1, k + 14, 98, 1, 3);
		world.setBlock(i + 4, j + 1, k + 15, 98, 1, 3);
		world.setBlock(i + 4, j + 1, k + 16, 98, 1, 3);
		world.setBlock(i + 4, j + 1, k + 17, 98, 1, 3);
		world.setBlock(i + 4, j + 1, k + 18, 98, 1, 3);
		world.setBlock(i + 4, j + 1, k + 19, 98, 1, 3);
		world.setBlock(i + 4, j + 1, k + 20, 98, 1, 3);
		world.setBlock(i + 4, j + 1, k + 21, 98, 1, 3);
		world.setBlock(i + 4, j + 1, k + 22, 98, 1, 3);
		world.setBlock(i + 4, j + 1, k + 23, 98, 1, 3);
		world.setBlock(i + 4, j + 1, k + 24, 98, 1, 3);
		world.setBlock(i + 4, j + 1, k + 25, 98, 1, 3);
		world.setBlock(i + 4, j + 1, k + 26, 98, 1, 3);
		world.setBlock(i + 4, j + 1, k + 27, 98, 1, 3);
		world.setBlock(i + 4, j + 1, k + 28, 98, 1, 3);
		world.setBlock(i + 4, j + 1, k + 29, 98, 1, 3);
		world.setBlock(i + 4, j + 1, k + 30, 98, 1, 3);
		world.setBlock(i + 4, j + 1, k + 31, 98, 2, 3);
		world.setBlock(i + 4, j + 2, k + 3, 98, 2, 3);
		world.setBlock(i + 4, j + 2, k + 4, 98, 1, 3);
		world.setBlock(i + 4, j + 2, k + 5, 98, 1, 3);
		world.setBlock(i + 4, j + 2, k + 6, 98, 1, 3);
		world.setBlock(i + 4, j + 2, k + 7, 98, 1, 3);
		world.setBlock(i + 4, j + 2, k + 8, 98, 1, 3);
		world.setBlock(i + 4, j + 2, k + 9, 98, 1, 3);
		world.setBlock(i + 4, j + 2, k + 10, 98, 1, 3);
		world.setBlock(i + 4, j + 2, k + 11, 98, 1, 3);
		world.setBlock(i + 4, j + 2, k + 12, 98, 1, 3);
		world.setBlock(i + 4, j + 2, k + 13, 98, 1, 3);
		world.setBlock(i + 4, j + 2, k + 14, 98, 1, 3);
		world.setBlock(i + 4, j + 2, k + 15, 98, 1, 3);
		world.setBlock(i + 4, j + 2, k + 16, 98, 1, 3);
		world.setBlock(i + 4, j + 2, k + 17, 98, 1, 3);
		world.setBlock(i + 4, j + 2, k + 18, 98, 1, 3);
		world.setBlock(i + 4, j + 2, k + 19, 98, 1, 3);
		world.setBlock(i + 4, j + 2, k + 20, 98, 1, 3);
		world.setBlock(i + 4, j + 2, k + 21, 98, 1, 3);
		world.setBlock(i + 4, j + 2, k + 22, 98, 1, 3);
		world.setBlock(i + 4, j + 2, k + 23, 98, 1, 3);
		world.setBlock(i + 4, j + 2, k + 24, 98, 1, 3);
		world.setBlock(i + 4, j + 2, k + 25, 98, 1, 3);
		world.setBlock(i + 4, j + 2, k + 26, 98, 1, 3);
		world.setBlock(i + 4, j + 2, k + 27, 98, 1, 3);
		world.setBlock(i + 4, j + 2, k + 28, 98, 1, 3);
		world.setBlock(i + 4, j + 2, k + 29, 98, 1, 3);
		world.setBlock(i + 4, j + 2, k + 30, 98, 1, 3);
		world.setBlock(i + 4, j + 2, k + 31, 98, 2, 3);
		world.setBlock(i + 4, j + 3, k + 3, 101, 0, 4);
		world.setBlock(i + 4, j + 3, k + 31, 98, 2, 3);
		world.setBlock(i + 4, j + 4, k + 3, 98, 2, 3);
		world.setBlock(i + 4, j + 4, k + 31, 98, 2, 3);
		world.setBlock(i + 4, j + 5, k + 3, 98, 2, 3);
		world.setBlock(i + 4, j + 5, k + 31, 98, 2, 3);
		world.setBlock(i + 4, j + 6, k + 3, 98, 2, 3);
		world.setBlock(i + 4, j + 6, k + 31, 98, 2, 3);
		world.setBlock(i + 4, j + 7, k + 0, 98, 3, 3);
		world.setBlock(i + 4, j + 7, k + 1, 98, 1, 3);
		world.setBlock(i + 4, j + 7, k + 2, 98, 1, 3);
		world.setBlock(i + 4, j + 7, k + 3, 98, 2, 3);
		world.setBlock(i + 4, j + 7, k + 31, 98, 1, 3);
		world.setBlock(i + 4, j + 7, k + 32, 98, 1, 3);
		world.setBlock(i + 4, j + 7, k + 33, 98, 1, 3);
		world.setBlock(i + 4, j + 7, k + 34, 98, 3, 3);
		world.setBlock(i + 4, j + 8, k + 3, 98, 2, 3);
		world.setBlock(i + 4, j + 8, k + 4, 98, 1, 3);
		world.setBlock(i + 4, j + 8, k + 5, 98, 1, 3);
		world.setBlock(i + 4, j + 8, k + 6, 98, 1, 3);
		world.setBlock(i + 4, j + 8, k + 7, 98, 1, 3);
		world.setBlock(i + 4, j + 8, k + 8, 98, 1, 3);
		world.setBlock(i + 4, j + 8, k + 9, 98, 1, 3);
		world.setBlock(i + 4, j + 8, k + 10, 98, 1, 3);
		world.setBlock(i + 4, j + 8, k + 11, 98, 1, 3);
		world.setBlock(i + 4, j + 8, k + 12, 98, 1, 3);
		world.setBlock(i + 4, j + 8, k + 13, 98, 1, 3);
		world.setBlock(i + 4, j + 8, k + 14, 98, 1, 3);
		world.setBlock(i + 4, j + 8, k + 15, 98, 1, 3);
		world.setBlock(i + 4, j + 8, k + 16, 98, 1, 3);
		world.setBlock(i + 4, j + 8, k + 17, 98, 1, 3);
		world.setBlock(i + 4, j + 8, k + 18, 98, 1, 3);
		world.setBlock(i + 4, j + 8, k + 19, 98, 1, 3);
		world.setBlock(i + 4, j + 8, k + 20, 98, 1, 3);
		world.setBlock(i + 4, j + 8, k + 21, 98, 1, 3);
		world.setBlock(i + 4, j + 8, k + 22, 98, 1, 3);
		world.setBlock(i + 4, j + 8, k + 23, 98, 1, 3);
		world.setBlock(i + 4, j + 8, k + 24, 98, 1, 3);
		world.setBlock(i + 4, j + 8, k + 25, 98, 1, 3);
		world.setBlock(i + 4, j + 8, k + 26, 98, 1, 3);
		world.setBlock(i + 4, j + 8, k + 27, 98, 1, 3);
		world.setBlock(i + 4, j + 8, k + 28, 98, 1, 3);
		world.setBlock(i + 4, j + 8, k + 29, 98, 1, 3);
		world.setBlock(i + 4, j + 8, k + 30, 98, 1, 3);
		world.setBlock(i + 4, j + 8, k + 31, 98, 2, 3);
		world.setBlock(i + 4, j + 9, k + 3, 98, 2, 3);
		world.setBlock(i + 4, j + 9, k + 31, 98, 2, 3);
		world.setBlock(i + 4, j + 10, k + 3, 98, 2, 3);
		world.setBlock(i + 4, j + 10, k + 31, 98, 2, 3);
		world.setBlock(i + 4, j + 11, k + 3, 98, 2, 3);
		world.setBlock(i + 4, j + 11, k + 31, 98, 2, 3);
		world.setBlock(i + 4, j + 12, k + 2, 30, 0, 4);
		world.setBlock(i + 4, j + 12, k + 3, 98, 2, 3);
		world.setBlock(i + 4, j + 12, k + 31, 98, 2, 3);
		world.setBlock(i + 4, j + 13, k + 0, 109, 2, 3);
		world.setBlock(i + 4, j + 13, k + 1, 98, 1, 3);
		world.setBlock(i + 4, j + 13, k + 2, 98, 1, 3);
		world.setBlock(i + 4, j + 13, k + 3, 98, 2, 3);
		world.setBlock(i + 4, j + 13, k + 31, 98, 2, 3);
		world.setBlock(i + 4, j + 13, k + 32, 98, 2, 3);
		world.setBlock(i + 4, j + 13, k + 34, 109, 3, 3);
		world.setBlock(i + 4, j + 14, k + 1, 98, 0, 4);
		world.setBlock(i + 4, j + 14, k + 2, 98, 0, 4);
		world.setBlock(i + 4, j + 14, k + 3, 98, 0, 4);
		world.setBlock(i + 4, j + 14, k + 4, 98, 0, 4);
		world.setBlock(i + 4, j + 14, k + 5, 98, 0, 4);
		world.setBlock(i + 4, j + 14, k + 6, 98, 0, 4);
		world.setBlock(i + 4, j + 14, k + 7, 98, 0, 4);
		world.setBlock(i + 4, j + 14, k + 8, 98, 0, 4);
		world.setBlock(i + 4, j + 14, k + 9, 98, 0, 4);
		world.setBlock(i + 4, j + 14, k + 10, 98, 0, 4);
		world.setBlock(i + 4, j + 14, k + 11, 98, 0, 4);
		world.setBlock(i + 4, j + 14, k + 12, 98, 0, 4);
		world.setBlock(i + 4, j + 14, k + 13, 98, 0, 4);
		world.setBlock(i + 4, j + 14, k + 14, 98, 0, 4);
		world.setBlock(i + 4, j + 14, k + 15, 98, 0, 4);
		world.setBlock(i + 4, j + 14, k + 16, 98, 0, 4);
		world.setBlock(i + 4, j + 14, k + 17, 98, 0, 4);
		world.setBlock(i + 4, j + 14, k + 18, 98, 0, 4);
		world.setBlock(i + 4, j + 14, k + 19, 98, 0, 4);
		world.setBlock(i + 4, j + 14, k + 20, 98, 0, 4);
		world.setBlock(i + 4, j + 14, k + 21, 98, 0, 4);
		world.setBlock(i + 4, j + 14, k + 22, 98, 0, 4);
		world.setBlock(i + 4, j + 14, k + 23, 98, 0, 4);
		world.setBlock(i + 4, j + 14, k + 24, 98, 0, 4);
		world.setBlock(i + 4, j + 14, k + 25, 98, 0, 4);
		world.setBlock(i + 4, j + 14, k + 26, 98, 0, 4);
		world.setBlock(i + 4, j + 14, k + 27, 98, 0, 4);
		world.setBlock(i + 4, j + 14, k + 28, 98, 0, 4);
		world.setBlock(i + 4, j + 14, k + 29, 98, 0, 4);
		world.setBlock(i + 4, j + 14, k + 30, 98, 0, 4);
		world.setBlock(i + 4, j + 14, k + 31, 98, 0, 4);
		world.setBlock(i + 4, j + 14, k + 32, 98, 0, 4);
		world.setBlock(i + 4, j + 14, k + 33, 98, 0, 4);
		world.setBlock(i + 5, j + 0, k + 0, 98, 0, 4);
		world.setBlock(i + 5, j + 0, k + 1, 98, 1, 3);
		world.setBlock(i + 5, j + 0, k + 2, 98, 1, 3);
		world.setBlock(i + 5, j + 0, k + 3, 98, 2, 3);
		world.setBlock(i + 5, j + 0, k + 4, 98, 1, 3);
		world.setBlock(i + 5, j + 0, k + 5, 98, 1, 3);
		world.setBlock(i + 5, j + 0, k + 6, 98, 1, 3);
		world.setBlock(i + 5, j + 0, k + 7, 98, 1, 3);
		world.setBlock(i + 5, j + 0, k + 8, 98, 1, 3);
		world.setBlock(i + 5, j + 0, k + 9, 98, 1, 3);
		world.setBlock(i + 5, j + 0, k + 10, 98, 1, 3);
		world.setBlock(i + 5, j + 0, k + 11, 98, 1, 3);
		world.setBlock(i + 5, j + 0, k + 12, 98, 1, 3);
		world.setBlock(i + 5, j + 0, k + 13, 98, 1, 3);
		world.setBlock(i + 5, j + 0, k + 14, 98, 1, 3);
		world.setBlock(i + 5, j + 0, k + 15, 98, 1, 3);
		world.setBlock(i + 5, j + 0, k + 16, 98, 1, 3);
		world.setBlock(i + 5, j + 0, k + 17, 98, 1, 3);
		world.setBlock(i + 5, j + 0, k + 18, 98, 1, 3);
		world.setBlock(i + 5, j + 0, k + 19, 98, 1, 3);
		world.setBlock(i + 5, j + 0, k + 20, 98, 1, 3);
		world.setBlock(i + 5, j + 0, k + 21, 98, 1, 3);
		world.setBlock(i + 5, j + 0, k + 22, 98, 1, 3);
		world.setBlock(i + 5, j + 0, k + 23, 98, 1, 3);
		world.setBlock(i + 5, j + 0, k + 24, 98, 1, 3);
		world.setBlock(i + 5, j + 0, k + 25, 98, 1, 3);
		world.setBlock(i + 5, j + 0, k + 26, 98, 1, 3);
		world.setBlock(i + 5, j + 0, k + 27, 98, 1, 3);
		world.setBlock(i + 5, j + 0, k + 28, 98, 1, 3);
		world.setBlock(i + 5, j + 0, k + 29, 98, 1, 3);
		world.setBlock(i + 5, j + 0, k + 30, 98, 1, 3);
		world.setBlock(i + 5, j + 0, k + 31, 98, 1, 3);
		world.setBlock(i + 5, j + 0, k + 32, 98, 1, 3);
		world.setBlock(i + 5, j + 0, k + 33, 98, 1, 3);
		world.setBlock(i + 5, j + 0, k + 34, 98, 0, 4);
		world.setBlock(i + 5, j + 1, k + 0, 109, 0, 4);
		world.setBlock(i + 5, j + 1, k + 1, 109, 0, 4);
		world.setBlock(i + 5, j + 1, k + 2, 109, 3, 3);
		world.setBlock(i + 5, j + 1, k + 3, 98, 2, 3);
		world.setBlock(i + 5, j + 1, k + 4, 98, 1, 3);
		world.setBlock(i + 5, j + 1, k + 5, 98, 1, 3);
		world.setBlock(i + 5, j + 1, k + 6, 98, 1, 3);
		world.setBlock(i + 5, j + 1, k + 7, 98, 1, 3);
		world.setBlock(i + 5, j + 1, k + 8, 98, 1, 3);
		world.setBlock(i + 5, j + 1, k + 9, 98, 1, 3);
		world.setBlock(i + 5, j + 1, k + 10, 98, 1, 3);
		world.setBlock(i + 5, j + 1, k + 11, 98, 1, 3);
		world.setBlock(i + 5, j + 1, k + 12, 98, 1, 3);
		world.setBlock(i + 5, j + 1, k + 13, 98, 1, 3);
		world.setBlock(i + 5, j + 1, k + 14, 98, 1, 3);
		world.setBlock(i + 5, j + 1, k + 15, 98, 1, 3);
		world.setBlock(i + 5, j + 1, k + 16, 98, 1, 3);
		world.setBlock(i + 5, j + 1, k + 17, 98, 1, 3);
		world.setBlock(i + 5, j + 1, k + 18, 98, 1, 3);
		world.setBlock(i + 5, j + 1, k + 19, 98, 1, 3);
		world.setBlock(i + 5, j + 1, k + 20, 98, 1, 3);
		world.setBlock(i + 5, j + 1, k + 21, 98, 1, 3);
		world.setBlock(i + 5, j + 1, k + 22, 98, 1, 3);
		world.setBlock(i + 5, j + 1, k + 23, 98, 1, 3);
		world.setBlock(i + 5, j + 1, k + 24, 98, 1, 3);
		world.setBlock(i + 5, j + 1, k + 25, 98, 1, 3);
		world.setBlock(i + 5, j + 1, k + 26, 98, 1, 3);
		world.setBlock(i + 5, j + 1, k + 27, 98, 1, 3);
		world.setBlock(i + 5, j + 1, k + 28, 98, 1, 3);
		world.setBlock(i + 5, j + 1, k + 29, 98, 1, 3);
		world.setBlock(i + 5, j + 1, k + 30, 98, 1, 3);
		world.setBlock(i + 5, j + 1, k + 31, 98, 2, 3);
		world.setBlock(i + 5, j + 2, k + 3, 98, 2, 3);
		world.setBlock(i + 5, j + 2, k + 4, 98, 1, 3);
		world.setBlock(i + 5, j + 2, k + 5, 98, 1, 3);
		world.setBlock(i + 5, j + 2, k + 6, 98, 1, 3);
		world.setBlock(i + 5, j + 2, k + 7, 98, 1, 3);
		world.setBlock(i + 5, j + 2, k + 8, 98, 1, 3);
		world.setBlock(i + 5, j + 2, k + 9, 98, 1, 3);
		world.setBlock(i + 5, j + 2, k + 10, 98, 1, 3);
		world.setBlock(i + 5, j + 2, k + 11, 98, 1, 3);
		world.setBlock(i + 5, j + 2, k + 12, 98, 1, 3);
		world.setBlock(i + 5, j + 2, k + 13, 98, 1, 3);
		world.setBlock(i + 5, j + 2, k + 14, 98, 1, 3);
		world.setBlock(i + 5, j + 2, k + 15, 98, 1, 3);
		world.setBlock(i + 5, j + 2, k + 16, 98, 1, 3);
		world.setBlock(i + 5, j + 2, k + 17, 98, 1, 3);
		world.setBlock(i + 5, j + 2, k + 18, 98, 1, 3);
		world.setBlock(i + 5, j + 2, k + 19, 98, 1, 3);
		world.setBlock(i + 5, j + 2, k + 20, 98, 1, 3);
		world.setBlock(i + 5, j + 2, k + 21, 98, 1, 3);
		world.setBlock(i + 5, j + 2, k + 22, 98, 1, 3);
		world.setBlock(i + 5, j + 2, k + 23, 98, 1, 3);
		world.setBlock(i + 5, j + 2, k + 24, 98, 1, 3);
		world.setBlock(i + 5, j + 2, k + 25, 98, 1, 3);
		world.setBlock(i + 5, j + 2, k + 26, 98, 1, 3);
		world.setBlock(i + 5, j + 2, k + 27, 98, 1, 3);
		world.setBlock(i + 5, j + 2, k + 28, 98, 1, 3);
		world.setBlock(i + 5, j + 2, k + 29, 98, 1, 3);
		world.setBlock(i + 5, j + 2, k + 30, 98, 1, 3);
		world.setBlock(i + 5, j + 2, k + 31, 98, 2, 3);
		world.setBlock(i + 5, j + 3, k + 3, 101, 0, 4);
		world.setBlock(i + 5, j + 3, k + 31, 98, 2, 3);
		world.setBlock(i + 5, j + 4, k + 3, 98, 2, 3);
		world.setBlock(i + 5, j + 4, k + 31, 101, 0, 4);
		world.setBlock(i + 5, j + 5, k + 3, 98, 2, 3);
		world.setBlock(i + 5, j + 5, k + 31, 98, 2, 3);
		world.setBlock(i + 5, j + 6, k + 3, 98, 2, 3);
		world.setBlock(i + 5, j + 6, k + 31, 98, 2, 3);
		world.setBlock(i + 5, j + 7, k + 0, 98, 3, 3);
		world.setBlock(i + 5, j + 7, k + 1, 98, 1, 3);
		world.setBlock(i + 5, j + 7, k + 2, 98, 1, 3);
		world.setBlock(i + 5, j + 7, k + 3, 98, 2, 3);
		world.setBlock(i + 5, j + 7, k + 27, 89, 0, 4);
		world.setBlock(i + 5, j + 7, k + 31, 98, 1, 3);
		world.setBlock(i + 5, j + 7, k + 32, 98, 1, 3);
		world.setBlock(i + 5, j + 7, k + 33, 98, 1, 3);
		world.setBlock(i + 5, j + 7, k + 34, 98, 3, 3);
		world.setBlock(i + 5, j + 8, k + 3, 98, 2, 3);
		world.setBlock(i + 5, j + 8, k + 4, 98, 1, 3);
		world.setBlock(i + 5, j + 8, k + 5, 98, 1, 3);
		world.setBlock(i + 5, j + 8, k + 6, 98, 1, 3);
		world.setBlock(i + 5, j + 8, k + 7, 98, 1, 3);
		world.setBlock(i + 5, j + 8, k + 8, 98, 1, 3);
		world.setBlock(i + 5, j + 8, k + 9, 98, 1, 3);
		world.setBlock(i + 5, j + 8, k + 10, 98, 1, 3);
		world.setBlock(i + 5, j + 8, k + 11, 98, 1, 3);
		world.setBlock(i + 5, j + 8, k + 12, 98, 1, 3);
		world.setBlock(i + 5, j + 8, k + 13, 98, 1, 3);
		world.setBlock(i + 5, j + 8, k + 14, 98, 1, 3);
		world.setBlock(i + 5, j + 8, k + 15, 98, 1, 3);
		world.setBlock(i + 5, j + 8, k + 16, 98, 1, 3);
		world.setBlock(i + 5, j + 8, k + 17, 98, 1, 3);
		world.setBlock(i + 5, j + 8, k + 18, 98, 1, 3);
		world.setBlock(i + 5, j + 8, k + 19, 98, 1, 3);
		world.setBlock(i + 5, j + 8, k + 20, 98, 1, 3);
		world.setBlock(i + 5, j + 8, k + 21, 98, 1, 3);
		world.setBlock(i + 5, j + 8, k + 22, 98, 1, 3);
		world.setBlock(i + 5, j + 8, k + 23, 98, 1, 3);
		world.setBlock(i + 5, j + 8, k + 24, 98, 1, 3);
		world.setBlock(i + 5, j + 8, k + 25, 98, 1, 3);
		world.setBlock(i + 5, j + 8, k + 26, 98, 1, 3);
		world.setBlock(i + 5, j + 8, k + 27, 98, 1, 3);
		world.setBlock(i + 5, j + 8, k + 28, 98, 1, 3);
		world.setBlock(i + 5, j + 8, k + 29, 98, 1, 3);
		world.setBlock(i + 5, j + 8, k + 30, 98, 1, 3);
		world.setBlock(i + 5, j + 8, k + 31, 98, 2, 3);
		world.setBlock(i + 5, j + 9, k + 3, 98, 2, 3);
		world.setBlock(i + 5, j + 9, k + 31, 98, 2, 3);
		world.setBlock(i + 5, j + 10, k + 3, 98, 2, 3);
		world.setBlock(i + 5, j + 10, k + 31, 98, 2, 3);
		world.setBlock(i + 5, j + 11, k + 3, 98, 2, 3);
		world.setBlock(i + 5, j + 11, k + 31, 98, 2, 3);
		world.setBlock(i + 5, j + 12, k + 0, 109, 4, 3);
		world.setBlock(i + 5, j + 12, k + 1, 109, 4, 3);
		world.setBlock(i + 5, j + 12, k + 2, 109, 7, 3);
		world.setBlock(i + 5, j + 12, k + 3, 98, 2, 3);
		world.setBlock(i + 5, j + 12, k + 31, 98, 2, 3);
		world.setBlock(i + 5, j + 13, k + 0, 109, 2, 3);
		world.setBlock(i + 5, j + 13, k + 1, 98, 1, 3);
		world.setBlock(i + 5, j + 13, k + 2, 98, 1, 3);
		world.setBlock(i + 5, j + 13, k + 3, 98, 2, 3);
		world.setBlock(i + 5, j + 13, k + 31, 98, 2, 3);
		world.setBlock(i + 5, j + 13, k + 32, 98, 2, 3);
		world.setBlock(i + 5, j + 13, k + 34, 109, 3, 3);
		world.setBlock(i + 5, j + 14, k + 1, 98, 0, 4);
		world.setBlock(i + 5, j + 14, k + 3, 98, 2, 3);
		world.setBlock(i + 5, j + 14, k + 31, 98, 2, 3);
		world.setBlock(i + 5, j + 14, k + 33, 98, 0, 4);
		world.setBlock(i + 5, j + 15, k + 1, 44, 5, 3);
		world.setBlock(i + 5, j + 15, k + 2, 44, 5, 3);
		world.setBlock(i + 5, j + 15, k + 3, 44, 5, 3);
		world.setBlock(i + 5, j + 15, k + 4, 44, 5, 3);
		world.setBlock(i + 5, j + 15, k + 5, 44, 5, 3);
		world.setBlock(i + 5, j + 15, k + 6, 44, 5, 3);
		world.setBlock(i + 5, j + 15, k + 7, 44, 5, 3);
		world.setBlock(i + 5, j + 15, k + 8, 44, 5, 3);
		world.setBlock(i + 5, j + 15, k + 9, 44, 5, 3);
		world.setBlock(i + 5, j + 15, k + 10, 44, 5, 3);
		world.setBlock(i + 5, j + 15, k + 11, 44, 5, 3);
		world.setBlock(i + 5, j + 15, k + 12, 44, 5, 3);
		world.setBlock(i + 5, j + 15, k + 13, 44, 5, 3);
		world.setBlock(i + 5, j + 15, k + 14, 44, 5, 3);
		world.setBlock(i + 5, j + 15, k + 15, 44, 5, 3);
		world.setBlock(i + 5, j + 15, k + 16, 44, 5, 3);
		world.setBlock(i + 5, j + 15, k + 17, 44, 5, 3);
		world.setBlock(i + 5, j + 15, k + 18, 44, 5, 3);
		world.setBlock(i + 5, j + 15, k + 19, 44, 5, 3);
		world.setBlock(i + 5, j + 15, k + 20, 44, 5, 3);
		world.setBlock(i + 5, j + 15, k + 21, 44, 5, 3);
		world.setBlock(i + 5, j + 15, k + 22, 44, 5, 3);
		world.setBlock(i + 5, j + 15, k + 23, 44, 5, 3);
		world.setBlock(i + 5, j + 15, k + 24, 44, 5, 3);
		world.setBlock(i + 5, j + 15, k + 25, 44, 5, 3);
		world.setBlock(i + 5, j + 15, k + 26, 44, 5, 3);
		world.setBlock(i + 5, j + 15, k + 27, 44, 5, 3);
		world.setBlock(i + 5, j + 15, k + 28, 44, 5, 3);
		world.setBlock(i + 5, j + 15, k + 29, 44, 5, 3);
		world.setBlock(i + 5, j + 15, k + 30, 44, 5, 3);
		world.setBlock(i + 5, j + 15, k + 31, 44, 5, 3);
		world.setBlock(i + 5, j + 15, k + 32, 44, 5, 3);
		world.setBlock(i + 5, j + 15, k + 33, 44, 5, 3);
		world.setBlock(i + 6, j + 0, k + 0, 98, 0, 4);
		world.setBlock(i + 6, j + 0, k + 1, 98, 1, 3);
		world.setBlock(i + 6, j + 0, k + 2, 98, 1, 3);
		world.setBlock(i + 6, j + 0, k + 3, 98, 2, 3);
		world.setBlock(i + 6, j + 0, k + 4, 98, 1, 3);
		world.setBlock(i + 6, j + 0, k + 5, 98, 1, 3);
		world.setBlock(i + 6, j + 0, k + 6, 98, 1, 3);
		world.setBlock(i + 6, j + 0, k + 7, 98, 1, 3);
		world.setBlock(i + 6, j + 0, k + 8, 98, 1, 3);
		world.setBlock(i + 6, j + 0, k + 9, 98, 1, 3);
		world.setBlock(i + 6, j + 0, k + 10, 98, 1, 3);
		world.setBlock(i + 6, j + 0, k + 11, 98, 1, 3);
		world.setBlock(i + 6, j + 0, k + 12, 98, 1, 3);
		world.setBlock(i + 6, j + 0, k + 13, 98, 1, 3);
		world.setBlock(i + 6, j + 0, k + 14, 98, 1, 3);
		world.setBlock(i + 6, j + 0, k + 15, 98, 1, 3);
		world.setBlock(i + 6, j + 0, k + 16, 98, 1, 3);
		world.setBlock(i + 6, j + 0, k + 17, 98, 1, 3);
		world.setBlock(i + 6, j + 0, k + 18, 98, 1, 3);
		world.setBlock(i + 6, j + 0, k + 19, 98, 1, 3);
		world.setBlock(i + 6, j + 0, k + 20, 98, 1, 3);
		world.setBlock(i + 6, j + 0, k + 21, 98, 1, 3);
		world.setBlock(i + 6, j + 0, k + 22, 98, 1, 3);
		world.setBlock(i + 6, j + 0, k + 23, 98, 1, 3);
		world.setBlock(i + 6, j + 0, k + 24, 98, 1, 3);
		world.setBlock(i + 6, j + 0, k + 25, 98, 1, 3);
		world.setBlock(i + 6, j + 0, k + 26, 98, 1, 3);
		world.setBlock(i + 6, j + 0, k + 27, 98, 1, 3);
		world.setBlock(i + 6, j + 0, k + 28, 98, 1, 3);
		world.setBlock(i + 6, j + 0, k + 29, 98, 1, 3);
		world.setBlock(i + 6, j + 0, k + 30, 98, 1, 3);
		world.setBlock(i + 6, j + 0, k + 31, 98, 1, 3);
		world.setBlock(i + 6, j + 0, k + 32, 98, 1, 3);
		world.setBlock(i + 6, j + 0, k + 33, 98, 1, 3);
		world.setBlock(i + 6, j + 0, k + 34, 98, 0, 4);
		world.setBlock(i + 6, j + 1, k + 0, 109, 2, 3);
		world.setBlock(i + 6, j + 1, k + 1, 98, 3, 3);
		world.setBlock(i + 6, j + 1, k + 2, 109, 3, 3);
		world.setBlock(i + 6, j + 1, k + 3, 98, 2, 3);
		world.setBlock(i + 6, j + 1, k + 4, 98, 1, 3);
		world.setBlock(i + 6, j + 1, k + 5, 98, 1, 3);
		world.setBlock(i + 6, j + 1, k + 6, 98, 1, 3);
		world.setBlock(i + 6, j + 1, k + 7, 98, 1, 3);
		world.setBlock(i + 6, j + 1, k + 8, 98, 1, 3);
		world.setBlock(i + 6, j + 1, k + 9, 98, 1, 3);
		world.setBlock(i + 6, j + 1, k + 10, 98, 1, 3);
		world.setBlock(i + 6, j + 1, k + 11, 98, 1, 3);
		world.setBlock(i + 6, j + 1, k + 12, 98, 1, 3);
		world.setBlock(i + 6, j + 1, k + 13, 98, 1, 3);
		world.setBlock(i + 6, j + 1, k + 14, 98, 1, 3);
		world.setBlock(i + 6, j + 1, k + 15, 98, 1, 3);
		world.setBlock(i + 6, j + 1, k + 16, 98, 1, 3);
		world.setBlock(i + 6, j + 1, k + 17, 98, 1, 3);
		world.setBlock(i + 6, j + 1, k + 18, 98, 1, 3);
		world.setBlock(i + 6, j + 1, k + 19, 98, 1, 3);
		world.setBlock(i + 6, j + 1, k + 20, 98, 1, 3);
		world.setBlock(i + 6, j + 1, k + 21, 98, 1, 3);
		world.setBlock(i + 6, j + 1, k + 22, 98, 1, 3);
		world.setBlock(i + 6, j + 1, k + 23, 98, 1, 3);
		world.setBlock(i + 6, j + 1, k + 24, 98, 1, 3);
		world.setBlock(i + 6, j + 1, k + 25, 98, 1, 3);
		world.setBlock(i + 6, j + 1, k + 26, 98, 1, 3);
		world.setBlock(i + 6, j + 1, k + 27, 98, 1, 3);
		world.setBlock(i + 6, j + 1, k + 28, 98, 1, 3);
		world.setBlock(i + 6, j + 1, k + 29, 98, 1, 3);
		world.setBlock(i + 6, j + 1, k + 30, 98, 1, 3);
		world.setBlock(i + 6, j + 1, k + 31, 98, 2, 3);
		world.setBlock(i + 6, j + 2, k + 1, 98, 3, 3);
		world.setBlock(i + 6, j + 2, k + 3, 98, 2, 3);
		world.setBlock(i + 6, j + 2, k + 4, 98, 1, 3);
		world.setBlock(i + 6, j + 2, k + 5, 98, 1, 3);
		world.setBlock(i + 6, j + 2, k + 6, 98, 1, 3);
		world.setBlock(i + 6, j + 2, k + 7, 98, 1, 3);
		world.setBlock(i + 6, j + 2, k + 8, 98, 1, 3);
		world.setBlock(i + 6, j + 2, k + 9, 98, 1, 3);
		world.setBlock(i + 6, j + 2, k + 10, 98, 1, 3);
		world.setBlock(i + 6, j + 2, k + 11, 98, 1, 3);
		world.setBlock(i + 6, j + 2, k + 12, 98, 1, 3);
		world.setBlock(i + 6, j + 2, k + 13, 98, 1, 3);
		world.setBlock(i + 6, j + 2, k + 14, 98, 1, 3);
		world.setBlock(i + 6, j + 2, k + 15, 98, 1, 3);
		world.setBlock(i + 6, j + 2, k + 16, 98, 1, 3);
		world.setBlock(i + 6, j + 2, k + 17, 98, 1, 3);
		world.setBlock(i + 6, j + 2, k + 18, 98, 1, 3);
		world.setBlock(i + 6, j + 2, k + 19, 98, 1, 3);
		world.setBlock(i + 6, j + 2, k + 20, 98, 1, 3);
		world.setBlock(i + 6, j + 2, k + 21, 98, 1, 3);
		world.setBlock(i + 6, j + 2, k + 22, 98, 1, 3);
		world.setBlock(i + 6, j + 2, k + 23, 98, 1, 3);
		world.setBlock(i + 6, j + 2, k + 24, 98, 1, 3);
		world.setBlock(i + 6, j + 2, k + 25, 98, 1, 3);
		world.setBlock(i + 6, j + 2, k + 26, 98, 1, 3);
		world.setBlock(i + 6, j + 2, k + 27, 98, 1, 3);
		world.setBlock(i + 6, j + 2, k + 28, 98, 1, 3);
		world.setBlock(i + 6, j + 2, k + 29, 98, 1, 3);
		world.setBlock(i + 6, j + 2, k + 30, 98, 1, 3);
		world.setBlock(i + 6, j + 2, k + 31, 98, 2, 3);
		world.setBlock(i + 6, j + 3, k + 1, 98, 3, 3);
		world.setBlock(i + 6, j + 3, k + 3, 98, 2, 3);
		world.setBlock(i + 6, j + 3, k + 25, 109, 2, 3);
		world.setBlock(i + 6, j + 3, k + 31, 98, 2, 3);
		world.setBlock(i + 6, j + 4, k + 1, 98, 3, 3);
		world.setBlock(i + 6, j + 4, k + 3, 98, 2, 3);
		world.setBlock(i + 6, j + 4, k + 26, 109, 2, 3);
		world.setBlock(i + 6, j + 4, k + 27, 98, 3, 3);
		world.setBlock(i + 6, j + 4, k + 28, 98, 3, 3);
		world.setBlock(i + 6, j + 4, k + 31, 98, 2, 3);
		world.setBlock(i + 6, j + 5, k + 1, 98, 3, 3);
		world.setBlock(i + 6, j + 5, k + 3, 98, 2, 3);
		world.setBlock(i + 6, j + 5, k + 31, 98, 2, 3);
		world.setBlock(i + 6, j + 6, k + 1, 98, 3, 3);
		world.setBlock(i + 6, j + 6, k + 3, 98, 2, 3);
		world.setBlock(i + 6, j + 6, k + 31, 98, 2, 3);
		world.setBlock(i + 6, j + 7, k + 0, 98, 3, 3);
		world.setBlock(i + 6, j + 7, k + 1, 98, 3, 3);
		world.setBlock(i + 6, j + 7, k + 2, 98, 1, 3);
		world.setBlock(i + 6, j + 7, k + 3, 98, 2, 3);
		world.setBlock(i + 6, j + 7, k + 6, 89, 0, 4);
		world.setBlock(i + 6, j + 7, k + 31, 98, 1, 3);
		world.setBlock(i + 6, j + 7, k + 32, 98, 1, 3);
		world.setBlock(i + 6, j + 7, k + 33, 98, 1, 3);
		world.setBlock(i + 6, j + 7, k + 34, 98, 3, 3);
		world.setBlock(i + 6, j + 8, k + 1, 98, 3, 3);
		world.setBlock(i + 6, j + 8, k + 3, 98, 2, 3);
		world.setBlock(i + 6, j + 8, k + 4, 98, 1, 3);
		world.setBlock(i + 6, j + 8, k + 5, 98, 1, 3);
		world.setBlock(i + 6, j + 8, k + 6, 98, 1, 3);
		world.setBlock(i + 6, j + 8, k + 7, 98, 1, 3);
		world.setBlock(i + 6, j + 8, k + 8, 98, 1, 3);
		world.setBlock(i + 6, j + 8, k + 9, 98, 1, 3);
		world.setBlock(i + 6, j + 8, k + 10, 98, 1, 3);
		world.setBlock(i + 6, j + 8, k + 11, 98, 1, 3);
		world.setBlock(i + 6, j + 8, k + 12, 98, 1, 3);
		world.setBlock(i + 6, j + 8, k + 13, 98, 1, 3);
		world.setBlock(i + 6, j + 8, k + 14, 98, 1, 3);
		world.setBlock(i + 6, j + 8, k + 15, 98, 1, 3);
		world.setBlock(i + 6, j + 8, k + 16, 98, 1, 3);
		world.setBlock(i + 6, j + 8, k + 17, 98, 1, 3);
		world.setBlock(i + 6, j + 8, k + 18, 98, 1, 3);
		world.setBlock(i + 6, j + 8, k + 19, 98, 1, 3);
		world.setBlock(i + 6, j + 8, k + 20, 98, 1, 3);
		world.setBlock(i + 6, j + 8, k + 21, 98, 1, 3);
		world.setBlock(i + 6, j + 8, k + 22, 98, 1, 3);
		world.setBlock(i + 6, j + 8, k + 23, 98, 1, 3);
		world.setBlock(i + 6, j + 8, k + 24, 98, 1, 3);
		world.setBlock(i + 6, j + 8, k + 25, 98, 1, 3);
		world.setBlock(i + 6, j + 8, k + 26, 98, 1, 3);
		world.setBlock(i + 6, j + 8, k + 27, 98, 1, 3);
		world.setBlock(i + 6, j + 8, k + 28, 98, 1, 3);
		world.setBlock(i + 6, j + 8, k + 31, 98, 2, 3);
		world.setBlock(i + 6, j + 9, k + 1, 98, 3, 3);
		world.setBlock(i + 6, j + 9, k + 3, 98, 2, 3);
		world.setBlock(i + 6, j + 9, k + 31, 98, 2, 3);
		world.setBlock(i + 6, j + 10, k + 1, 98, 3, 3);
		world.setBlock(i + 6, j + 10, k + 3, 101, 0, 4);
		world.setBlock(i + 6, j + 10, k + 31, 98, 2, 3);
		world.setBlock(i + 6, j + 11, k + 1, 98, 3, 3);
		world.setBlock(i + 6, j + 11, k + 3, 98, 2, 3);
		world.setBlock(i + 6, j + 11, k + 31, 98, 2, 3);
		world.setBlock(i + 6, j + 12, k + 0, 109, 6, 3);
		world.setBlock(i + 6, j + 12, k + 1, 98, 3, 3);
		world.setBlock(i + 6, j + 12, k + 2, 98, 3, 3);
		world.setBlock(i + 6, j + 12, k + 3, 98, 2, 3);
		world.setBlock(i + 6, j + 12, k + 31, 98, 2, 3);
		world.setBlock(i + 6, j + 13, k + 0, 109, 2, 3);
		world.setBlock(i + 6, j + 13, k + 1, 98, 1, 3);
		world.setBlock(i + 6, j + 13, k + 2, 98, 1, 3);
		world.setBlock(i + 6, j + 13, k + 3, 98, 2, 3);
		world.setBlock(i + 6, j + 13, k + 31, 98, 2, 3);
		world.setBlock(i + 6, j + 13, k + 32, 98, 2, 3);
		world.setBlock(i + 6, j + 13, k + 34, 109, 3, 3);
		world.setBlock(i + 6, j + 14, k + 1, 98, 0, 4);
		world.setBlock(i + 6, j + 14, k + 3, 98, 2, 3);
		world.setBlock(i + 6, j + 14, k + 31, 98, 2, 3);
		world.setBlock(i + 6, j + 14, k + 33, 98, 0, 4);
		world.setBlock(i + 6, j + 15, k + 1, 44, 5, 3);
		world.setBlock(i + 6, j + 15, k + 2, 44, 5, 3);
		world.setBlock(i + 6, j + 15, k + 3, 44, 5, 3);
		world.setBlock(i + 6, j + 15, k + 4, 44, 5, 3);
		world.setBlock(i + 6, j + 15, k + 5, 44, 5, 3);
		world.setBlock(i + 6, j + 15, k + 6, 44, 5, 3);
		world.setBlock(i + 6, j + 15, k + 7, 44, 5, 3);
		world.setBlock(i + 6, j + 15, k + 8, 44, 5, 3);
		world.setBlock(i + 6, j + 15, k + 9, 44, 5, 3);
		world.setBlock(i + 6, j + 15, k + 10, 44, 5, 3);
		world.setBlock(i + 6, j + 15, k + 11, 44, 5, 3);
		world.setBlock(i + 6, j + 15, k + 12, 44, 5, 3);
		world.setBlock(i + 6, j + 15, k + 13, 44, 5, 3);
		world.setBlock(i + 6, j + 15, k + 14, 44, 5, 3);
		world.setBlock(i + 6, j + 15, k + 15, 44, 5, 3);
		world.setBlock(i + 6, j + 15, k + 16, 44, 5, 3);
		world.setBlock(i + 6, j + 15, k + 17, 44, 5, 3);
		world.setBlock(i + 6, j + 15, k + 18, 44, 5, 3);
		world.setBlock(i + 6, j + 15, k + 19, 44, 5, 3);
		world.setBlock(i + 6, j + 15, k + 20, 44, 5, 3);
		world.setBlock(i + 6, j + 15, k + 21, 44, 5, 3);
		world.setBlock(i + 6, j + 15, k + 22, 44, 5, 3);
		world.setBlock(i + 6, j + 15, k + 23, 44, 5, 3);
		world.setBlock(i + 6, j + 15, k + 24, 44, 5, 3);
		world.setBlock(i + 6, j + 15, k + 25, 44, 5, 3);
		world.setBlock(i + 6, j + 15, k + 26, 44, 5, 3);
		world.setBlock(i + 6, j + 15, k + 27, 44, 5, 3);
		world.setBlock(i + 6, j + 15, k + 28, 44, 5, 3);
		world.setBlock(i + 6, j + 15, k + 29, 44, 5, 3);
		world.setBlock(i + 6, j + 15, k + 30, 44, 5, 3);
		world.setBlock(i + 6, j + 15, k + 31, 44, 5, 3);
		world.setBlock(i + 6, j + 15, k + 32, 44, 5, 3);
		world.setBlock(i + 6, j + 15, k + 33, 44, 5, 3);
		world.setBlock(i + 7, j + 0, k + 0, 98, 0, 4);
		world.setBlock(i + 7, j + 0, k + 1, 98, 1, 3);
		world.setBlock(i + 7, j + 0, k + 2, 98, 1, 3);
		world.setBlock(i + 7, j + 0, k + 3, 98, 2, 3);
		world.setBlock(i + 7, j + 0, k + 4, 98, 1, 3);
		world.setBlock(i + 7, j + 0, k + 5, 98, 1, 3);
		world.setBlock(i + 7, j + 0, k + 6, 98, 1, 3);
		world.setBlock(i + 7, j + 0, k + 7, 98, 1, 3);
		world.setBlock(i + 7, j + 0, k + 8, 98, 1, 3);
		world.setBlock(i + 7, j + 0, k + 9, 98, 1, 3);
		world.setBlock(i + 7, j + 0, k + 10, 98, 1, 3);
		world.setBlock(i + 7, j + 0, k + 11, 98, 1, 3);
		world.setBlock(i + 7, j + 0, k + 12, 98, 1, 3);
		world.setBlock(i + 7, j + 0, k + 13, 98, 1, 3);
		world.setBlock(i + 7, j + 0, k + 14, 98, 1, 3);
		world.setBlock(i + 7, j + 0, k + 15, 98, 1, 3);
		world.setBlock(i + 7, j + 0, k + 16, 98, 1, 3);
		world.setBlock(i + 7, j + 0, k + 17, 98, 1, 3);
		world.setBlock(i + 7, j + 0, k + 18, 98, 1, 3);
		world.setBlock(i + 7, j + 0, k + 19, 98, 1, 3);
		world.setBlock(i + 7, j + 0, k + 20, 98, 1, 3);
		world.setBlock(i + 7, j + 0, k + 21, 98, 1, 3);
		world.setBlock(i + 7, j + 0, k + 22, 98, 1, 3);
		world.setBlock(i + 7, j + 0, k + 23, 98, 1, 3);
		world.setBlock(i + 7, j + 0, k + 24, 98, 1, 3);
		world.setBlock(i + 7, j + 0, k + 25, 98, 1, 3);
		world.setBlock(i + 7, j + 0, k + 26, 98, 1, 3);
		world.setBlock(i + 7, j + 0, k + 27, 98, 1, 3);
		world.setBlock(i + 7, j + 0, k + 28, 98, 1, 3);
		world.setBlock(i + 7, j + 0, k + 29, 98, 1, 3);
		world.setBlock(i + 7, j + 0, k + 30, 98, 1, 3);
		world.setBlock(i + 7, j + 0, k + 31, 98, 1, 3);
		world.setBlock(i + 7, j + 0, k + 32, 98, 1, 3);
		world.setBlock(i + 7, j + 0, k + 33, 98, 1, 3);
		world.setBlock(i + 7, j + 0, k + 34, 98, 0, 4);
		world.setBlock(i + 7, j + 1, k + 0, 109, 1, 3);
		world.setBlock(i + 7, j + 1, k + 1, 109, 1, 3);
		world.setBlock(i + 7, j + 1, k + 2, 109, 1, 3);
		world.setBlock(i + 7, j + 1, k + 3, 98, 2, 3);
		world.setBlock(i + 7, j + 1, k + 4, 98, 1, 3);
		world.setBlock(i + 7, j + 1, k + 5, 98, 1, 3);
		world.setBlock(i + 7, j + 1, k + 6, 98, 1, 3);
		world.setBlock(i + 7, j + 1, k + 7, 98, 1, 3);
		world.setBlock(i + 7, j + 1, k + 8, 98, 1, 3);
		world.setBlock(i + 7, j + 1, k + 9, 98, 1, 3);
		world.setBlock(i + 7, j + 1, k + 10, 98, 1, 3);
		world.setBlock(i + 7, j + 1, k + 11, 98, 1, 3);
		world.setBlock(i + 7, j + 1, k + 12, 98, 1, 3);
		world.setBlock(i + 7, j + 1, k + 13, 98, 1, 3);
		world.setBlock(i + 7, j + 1, k + 14, 98, 1, 3);
		world.setBlock(i + 7, j + 1, k + 15, 98, 1, 3);
		world.setBlock(i + 7, j + 1, k + 16, 98, 1, 3);
		world.setBlock(i + 7, j + 1, k + 17, 98, 1, 3);
		world.setBlock(i + 7, j + 1, k + 18, 98, 1, 3);
		world.setBlock(i + 7, j + 1, k + 19, 98, 1, 3);
		world.setBlock(i + 7, j + 1, k + 20, 98, 1, 3);
		world.setBlock(i + 7, j + 1, k + 21, 98, 1, 3);
		world.setBlock(i + 7, j + 1, k + 22, 98, 1, 3);
		world.setBlock(i + 7, j + 1, k + 23, 98, 1, 3);
		world.setBlock(i + 7, j + 1, k + 24, 98, 1, 3);
		world.setBlock(i + 7, j + 1, k + 25, 98, 1, 3);
		world.setBlock(i + 7, j + 1, k + 26, 98, 1, 3);
		world.setBlock(i + 7, j + 1, k + 27, 98, 1, 3);
		world.setBlock(i + 7, j + 1, k + 28, 98, 1, 3);
		world.setBlock(i + 7, j + 1, k + 29, 98, 1, 3);
		world.setBlock(i + 7, j + 1, k + 30, 98, 1, 3);
		world.setBlock(i + 7, j + 1, k + 31, 98, 2, 3);
		world.setBlock(i + 7, j + 2, k + 3, 98, 2, 3);
		world.setBlock(i + 7, j + 2, k + 4, 98, 1, 3);
		world.setBlock(i + 7, j + 2, k + 5, 98, 1, 3);
		world.setBlock(i + 7, j + 2, k + 6, 98, 1, 3);
		world.setBlock(i + 7, j + 2, k + 7, 98, 1, 3);
		world.setBlock(i + 7, j + 2, k + 8, 98, 1, 3);
		world.setBlock(i + 7, j + 2, k + 9, 98, 1, 3);
		world.setBlock(i + 7, j + 2, k + 10, 98, 1, 3);
		world.setBlock(i + 7, j + 2, k + 11, 98, 1, 3);
		world.setBlock(i + 7, j + 2, k + 12, 98, 1, 3);
		world.setBlock(i + 7, j + 2, k + 13, 98, 1, 3);
		world.setBlock(i + 7, j + 2, k + 14, 98, 1, 3);
		world.setBlock(i + 7, j + 2, k + 15, 98, 1, 3);
		world.setBlock(i + 7, j + 2, k + 16, 98, 1, 3);
		world.setBlock(i + 7, j + 2, k + 17, 98, 1, 3);
		world.setBlock(i + 7, j + 2, k + 18, 98, 1, 3);
		world.setBlock(i + 7, j + 2, k + 19, 98, 1, 3);
		world.setBlock(i + 7, j + 2, k + 20, 98, 1, 3);
		world.setBlock(i + 7, j + 2, k + 21, 98, 1, 3);
		world.setBlock(i + 7, j + 2, k + 22, 98, 1, 3);
		world.setBlock(i + 7, j + 2, k + 23, 98, 1, 3);
		world.setBlock(i + 7, j + 2, k + 24, 98, 1, 3);
		world.setBlock(i + 7, j + 2, k + 25, 98, 1, 3);
		world.setBlock(i + 7, j + 2, k + 26, 98, 1, 3);
		world.setBlock(i + 7, j + 2, k + 27, 98, 1, 3);
		world.setBlock(i + 7, j + 2, k + 28, 98, 1, 3);
		world.setBlock(i + 7, j + 2, k + 29, 98, 1, 3);
		world.setBlock(i + 7, j + 2, k + 30, 98, 1, 3);
		world.setBlock(i + 7, j + 2, k + 31, 98, 2, 3);
		world.setBlock(i + 7, j + 3, k + 3, 98, 2, 3);
		world.setBlock(i + 7, j + 3, k + 25, 109, 2, 3);
		world.setBlock(i + 7, j + 3, k + 31, 98, 2, 3);
		world.setBlock(i + 7, j + 4, k + 3, 98, 2, 3);
		world.setBlock(i + 7, j + 4, k + 26, 109, 2, 3);
		world.setBlock(i + 7, j + 4, k + 27, 98, 3, 3);
		world.setBlock(i + 7, j + 4, k + 28, 98, 3, 3);
		world.setBlock(i + 7, j + 4, k + 31, 98, 2, 3);
		world.setBlock(i + 7, j + 5, k + 3, 98, 2, 3);

		generate2(world, rand, i, j, k);
		return true;
	}

	public boolean generate2(World world, Random rand, int i, int j, int k) {
		world.setBlock(i + 7, j + 5, k + 31, 98, 2, 3);
		world.setBlock(i + 7, j + 6, k + 3, 98, 2, 3);
		world.setBlock(i + 7, j + 6, k + 31, 98, 2, 3);
		world.setBlock(i + 7, j + 7, k + 0, 98, 3, 3);
		world.setBlock(i + 7, j + 7, k + 1, 98, 1, 3);
		world.setBlock(i + 7, j + 7, k + 2, 98, 1, 3);
		world.setBlock(i + 7, j + 7, k + 3, 98, 2, 3);
		world.setBlock(i + 7, j + 7, k + 17, 89, 0, 4);
		world.setBlock(i + 7, j + 7, k + 31, 98, 1, 3);
		world.setBlock(i + 7, j + 7, k + 32, 98, 1, 3);
		world.setBlock(i + 7, j + 7, k + 33, 98, 1, 3);
		world.setBlock(i + 7, j + 7, k + 34, 98, 3, 3);
		world.setBlock(i + 7, j + 8, k + 3, 98, 2, 3);
		world.setBlock(i + 7, j + 8, k + 4, 98, 1, 3);
		world.setBlock(i + 7, j + 8, k + 5, 98, 1, 3);
		world.setBlock(i + 7, j + 8, k + 6, 98, 1, 3);
		world.setBlock(i + 7, j + 8, k + 7, 98, 1, 3);
		world.setBlock(i + 7, j + 8, k + 8, 98, 1, 3);
		world.setBlock(i + 7, j + 8, k + 9, 98, 1, 3);
		world.setBlock(i + 7, j + 8, k + 10, 98, 1, 3);
		world.setBlock(i + 7, j + 8, k + 11, 98, 1, 3);
		world.setBlock(i + 7, j + 8, k + 12, 98, 1, 3);
		world.setBlock(i + 7, j + 8, k + 13, 98, 1, 3);
		world.setBlock(i + 7, j + 8, k + 14, 98, 1, 3);
		world.setBlock(i + 7, j + 8, k + 15, 98, 1, 3);
		world.setBlock(i + 7, j + 8, k + 16, 98, 1, 3);
		world.setBlock(i + 7, j + 8, k + 17, 98, 1, 3);
		world.setBlock(i + 7, j + 8, k + 18, 98, 1, 3);
		world.setBlock(i + 7, j + 8, k + 19, 98, 1, 3);
		world.setBlock(i + 7, j + 8, k + 20, 98, 1, 3);
		world.setBlock(i + 7, j + 8, k + 21, 98, 1, 3);
		world.setBlock(i + 7, j + 8, k + 22, 98, 1, 3);
		world.setBlock(i + 7, j + 8, k + 23, 98, 1, 3);
		world.setBlock(i + 7, j + 8, k + 24, 98, 1, 3);
		world.setBlock(i + 7, j + 8, k + 25, 98, 1, 3);
		world.setBlock(i + 7, j + 8, k + 26, 98, 1, 3);
		world.setBlock(i + 7, j + 8, k + 27, 98, 1, 3);
		world.setBlock(i + 7, j + 8, k + 28, 98, 1, 3);
		world.setBlock(i + 7, j + 8, k + 31, 98, 2, 3);
		world.setBlock(i + 7, j + 9, k + 3, 98, 2, 3);
		world.setBlock(i + 7, j + 9, k + 31, 98, 2, 3);
		world.setBlock(i + 7, j + 10, k + 3, 98, 2, 3);
		world.setBlock(i + 7, j + 10, k + 31, 98, 2, 3);
		world.setBlock(i + 7, j + 11, k + 3, 98, 2, 3);
		world.setBlock(i + 7, j + 11, k + 31, 98, 2, 3);
		world.setBlock(i + 7, j + 12, k + 0, 109, 5, 3);
		world.setBlock(i + 7, j + 12, k + 1, 109, 5, 3);
		world.setBlock(i + 7, j + 12, k + 2, 109, 5, 3);
		world.setBlock(i + 7, j + 12, k + 3, 98, 2, 3);
		world.setBlock(i + 7, j + 12, k + 31, 98, 2, 3);
		world.setBlock(i + 7, j + 13, k + 0, 109, 2, 3);
		world.setBlock(i + 7, j + 13, k + 1, 98, 1, 3);
		world.setBlock(i + 7, j + 13, k + 2, 98, 1, 3);
		world.setBlock(i + 7, j + 13, k + 3, 98, 2, 3);
		world.setBlock(i + 7, j + 13, k + 31, 98, 2, 3);
		world.setBlock(i + 7, j + 13, k + 32, 98, 2, 3);
		world.setBlock(i + 7, j + 13, k + 34, 109, 3, 3);
		world.setBlock(i + 7, j + 14, k + 1, 98, 0, 4);
		world.setBlock(i + 7, j + 14, k + 3, 98, 2, 3);
		world.setBlock(i + 7, j + 14, k + 6, 89, 0, 4);
		world.setBlock(i + 7, j + 14, k + 14, 89, 0, 4);
		world.setBlock(i + 7, j + 14, k + 21, 89, 0, 4);
		world.setBlock(i + 7, j + 14, k + 27, 89, 0, 4);
		world.setBlock(i + 7, j + 14, k + 31, 98, 2, 3);
		world.setBlock(i + 7, j + 14, k + 33, 98, 0, 4);
		world.setBlock(i + 7, j + 15, k + 1, 98, 0, 4);
		world.setBlock(i + 7, j + 15, k + 2, 98, 0, 4);
		world.setBlock(i + 7, j + 15, k + 3, 98, 0, 4);
		world.setBlock(i + 7, j + 15, k + 4, 98, 0, 4);
		world.setBlock(i + 7, j + 15, k + 5, 98, 0, 4);
		world.setBlock(i + 7, j + 15, k + 6, 98, 0, 4);
		world.setBlock(i + 7, j + 15, k + 7, 98, 0, 4);
		world.setBlock(i + 7, j + 15, k + 8, 98, 0, 4);
		world.setBlock(i + 7, j + 15, k + 9, 98, 0, 4);
		world.setBlock(i + 7, j + 15, k + 10, 98, 0, 4);
		world.setBlock(i + 7, j + 15, k + 11, 98, 0, 4);
		world.setBlock(i + 7, j + 15, k + 12, 98, 0, 4);
		world.setBlock(i + 7, j + 15, k + 13, 98, 0, 4);
		world.setBlock(i + 7, j + 15, k + 14, 98, 0, 4);
		world.setBlock(i + 7, j + 15, k + 15, 98, 0, 4);
		world.setBlock(i + 7, j + 15, k + 16, 98, 0, 4);
		world.setBlock(i + 7, j + 15, k + 17, 98, 0, 4);
		world.setBlock(i + 7, j + 15, k + 18, 98, 0, 4);
		world.setBlock(i + 7, j + 15, k + 19, 98, 0, 4);
		world.setBlock(i + 7, j + 15, k + 20, 98, 0, 4);
		world.setBlock(i + 7, j + 15, k + 21, 98, 0, 4);
		world.setBlock(i + 7, j + 15, k + 22, 98, 0, 4);
		world.setBlock(i + 7, j + 15, k + 23, 98, 0, 4);
		world.setBlock(i + 7, j + 15, k + 24, 98, 0, 4);
		world.setBlock(i + 7, j + 15, k + 25, 98, 0, 4);
		world.setBlock(i + 7, j + 15, k + 26, 98, 0, 4);
		world.setBlock(i + 7, j + 15, k + 27, 98, 0, 4);
		world.setBlock(i + 7, j + 15, k + 28, 98, 0, 4);
		world.setBlock(i + 7, j + 15, k + 29, 98, 0, 4);
		world.setBlock(i + 7, j + 15, k + 30, 98, 0, 4);
		world.setBlock(i + 7, j + 15, k + 31, 98, 0, 4);
		world.setBlock(i + 7, j + 15, k + 32, 98, 0, 4);
		world.setBlock(i + 7, j + 15, k + 33, 98, 0, 4);
		world.setBlock(i + 8, j + 0, k + 0, 98, 2, 3);
		world.setBlock(i + 8, j + 0, k + 1, 98, 1, 3);
		world.setBlock(i + 8, j + 0, k + 2, 98, 1, 3);
		world.setBlock(i + 8, j + 0, k + 3, 98, 2, 3);
		world.setBlock(i + 8, j + 0, k + 4, 98, 1, 3);
		world.setBlock(i + 8, j + 0, k + 5, 98, 1, 3);
		world.setBlock(i + 8, j + 0, k + 6, 98, 1, 3);
		world.setBlock(i + 8, j + 0, k + 7, 98, 1, 3);
		world.setBlock(i + 8, j + 0, k + 8, 98, 1, 3);
		world.setBlock(i + 8, j + 0, k + 9, 98, 1, 3);
		world.setBlock(i + 8, j + 0, k + 10, 98, 1, 3);
		world.setBlock(i + 8, j + 0, k + 11, 98, 1, 3);
		world.setBlock(i + 8, j + 0, k + 12, 98, 1, 3);
		world.setBlock(i + 8, j + 0, k + 13, 98, 1, 3);
		world.setBlock(i + 8, j + 0, k + 14, 98, 1, 3);
		world.setBlock(i + 8, j + 0, k + 15, 98, 1, 3);
		world.setBlock(i + 8, j + 0, k + 16, 98, 1, 3);
		world.setBlock(i + 8, j + 0, k + 17, 98, 1, 3);
		world.setBlock(i + 8, j + 0, k + 18, 98, 1, 3);
		world.setBlock(i + 8, j + 0, k + 19, 98, 1, 3);
		world.setBlock(i + 8, j + 0, k + 20, 98, 1, 3);
		world.setBlock(i + 8, j + 0, k + 21, 98, 1, 3);
		world.setBlock(i + 8, j + 0, k + 22, 98, 1, 3);
		world.setBlock(i + 8, j + 0, k + 23, 98, 1, 3);
		world.setBlock(i + 8, j + 0, k + 24, 98, 1, 3);
		world.setBlock(i + 8, j + 0, k + 25, 98, 1, 3);
		world.setBlock(i + 8, j + 0, k + 26, 98, 1, 3);
		world.setBlock(i + 8, j + 0, k + 27, 98, 1, 3);
		world.setBlock(i + 8, j + 0, k + 28, 98, 1, 3);
		world.setBlock(i + 8, j + 0, k + 29, 98, 1, 3);
		world.setBlock(i + 8, j + 0, k + 30, 98, 1, 3);
		world.setBlock(i + 8, j + 0, k + 31, 98, 1, 3);
		world.setBlock(i + 8, j + 0, k + 32, 98, 1, 3);
		world.setBlock(i + 8, j + 0, k + 33, 98, 1, 3);
		world.setBlock(i + 8, j + 0, k + 34, 98, 0, 4);
		world.setBlock(i + 8, j + 1, k + 3, 98, 2, 3);
		world.setBlock(i + 8, j + 1, k + 4, 98, 1, 3);
		world.setBlock(i + 8, j + 1, k + 5, 98, 1, 3);
		world.setBlock(i + 8, j + 1, k + 6, 98, 1, 3);
		world.setBlock(i + 8, j + 1, k + 7, 98, 1, 3);
		world.setBlock(i + 8, j + 1, k + 8, 98, 1, 3);
		world.setBlock(i + 8, j + 1, k + 9, 98, 1, 3);
		world.setBlock(i + 8, j + 1, k + 10, 98, 1, 3);
		world.setBlock(i + 8, j + 1, k + 11, 98, 1, 3);
		world.setBlock(i + 8, j + 1, k + 12, 98, 1, 3);
		world.setBlock(i + 8, j + 1, k + 13, 98, 1, 3);
		world.setBlock(i + 8, j + 1, k + 14, 98, 1, 3);
		world.setBlock(i + 8, j + 1, k + 15, 98, 1, 3);
		world.setBlock(i + 8, j + 1, k + 16, 98, 1, 3);
		world.setBlock(i + 8, j + 1, k + 17, 98, 1, 3);
		world.setBlock(i + 8, j + 1, k + 18, 98, 1, 3);
		world.setBlock(i + 8, j + 1, k + 19, 98, 1, 3);
		world.setBlock(i + 8, j + 1, k + 20, 98, 1, 3);
		world.setBlock(i + 8, j + 1, k + 21, 98, 1, 3);
		world.setBlock(i + 8, j + 1, k + 22, 98, 1, 3);
		world.setBlock(i + 8, j + 1, k + 23, 98, 1, 3);
		world.setBlock(i + 8, j + 1, k + 24, 98, 1, 3);
		world.setBlock(i + 8, j + 1, k + 25, 98, 1, 3);
		world.setBlock(i + 8, j + 1, k + 26, 98, 1, 3);
		world.setBlock(i + 8, j + 1, k + 27, 98, 1, 3);
		world.setBlock(i + 8, j + 1, k + 28, 98, 1, 3);
		world.setBlock(i + 8, j + 1, k + 29, 98, 1, 3);
		world.setBlock(i + 8, j + 1, k + 30, 98, 1, 3);
		world.setBlock(i + 8, j + 1, k + 31, 98, 2, 3);
		world.setBlock(i + 8, j + 2, k + 3, 98, 2, 3);
		world.setBlock(i + 8, j + 2, k + 4, 98, 1, 3);
		world.setBlock(i + 8, j + 2, k + 5, 98, 1, 3);
		world.setBlock(i + 8, j + 2, k + 6, 98, 1, 3);
		world.setBlock(i + 8, j + 2, k + 7, 98, 1, 3);
		world.setBlock(i + 8, j + 2, k + 8, 98, 1, 3);
		world.setBlock(i + 8, j + 2, k + 9, 98, 1, 3);
		world.setBlock(i + 8, j + 2, k + 10, 98, 1, 3);
		world.setBlock(i + 8, j + 2, k + 11, 98, 1, 3);
		world.setBlock(i + 8, j + 2, k + 12, 98, 1, 3);
		world.setBlock(i + 8, j + 2, k + 13, 98, 1, 3);
		world.setBlock(i + 8, j + 2, k + 14, 98, 1, 3);
		world.setBlock(i + 8, j + 2, k + 15, 98, 1, 3);
		world.setBlock(i + 8, j + 2, k + 16, 98, 1, 3);
		world.setBlock(i + 8, j + 2, k + 17, 98, 1, 3);
		world.setBlock(i + 8, j + 2, k + 18, 98, 1, 3);
		world.setBlock(i + 8, j + 2, k + 19, 98, 1, 3);
		world.setBlock(i + 8, j + 2, k + 20, 98, 1, 3);
		world.setBlock(i + 8, j + 2, k + 21, 98, 1, 3);
		world.setBlock(i + 8, j + 2, k + 22, 98, 1, 3);
		world.setBlock(i + 8, j + 2, k + 23, 98, 1, 3);
		world.setBlock(i + 8, j + 2, k + 24, 98, 1, 3);
		world.setBlock(i + 8, j + 2, k + 25, 98, 1, 3);
		world.setBlock(i + 8, j + 2, k + 26, 98, 1, 3);
		world.setBlock(i + 8, j + 2, k + 27, 98, 1, 3);
		world.setBlock(i + 8, j + 2, k + 28, 98, 1, 3);
		world.setBlock(i + 8, j + 2, k + 29, 98, 1, 3);
		world.setBlock(i + 8, j + 2, k + 30, 98, 1, 3);
		world.setBlock(i + 8, j + 2, k + 31, 98, 2, 3);
		world.setBlock(i + 8, j + 3, k + 3, 98, 2, 3);
		world.setBlock(i + 8, j + 3, k + 31, 98, 2, 3);
		world.setBlock(i + 8, j + 4, k + 3, 98, 2, 3);
		world.setBlock(i + 8, j + 4, k + 27, 109, 5, 3);
		world.setBlock(i + 8, j + 4, k + 28, 109, 5, 3);
		world.setBlock(i + 8, j + 4, k + 31, 98, 2, 3);
		world.setBlock(i + 8, j + 5, k + 3, 101, 0, 4);
		world.setBlock(i + 8, j + 5, k + 27, 109, 0, 4);
		world.setBlock(i + 8, j + 5, k + 28, 109, 0, 4);
		world.setBlock(i + 8, j + 5, k + 31, 98, 2, 3);
		world.setBlock(i + 8, j + 6, k + 3, 98, 2, 3);
		world.setBlock(i + 8, j + 6, k + 31, 98, 2, 3);
		world.setBlock(i + 8, j + 7, k + 0, 98, 3, 3);
		world.setBlock(i + 8, j + 7, k + 1, 98, 1, 3);
		world.setBlock(i + 8, j + 7, k + 2, 98, 1, 3);
		world.setBlock(i + 8, j + 7, k + 3, 98, 2, 3);
		world.setBlock(i + 8, j + 7, k + 31, 98, 2, 3);
		world.setBlock(i + 8, j + 7, k + 32, 98, 1, 3);
		world.setBlock(i + 8, j + 7, k + 33, 98, 1, 3);
		world.setBlock(i + 8, j + 7, k + 34, 98, 3, 3);
		world.setBlock(i + 8, j + 8, k + 3, 98, 2, 3);
		world.setBlock(i + 8, j + 8, k + 4, 98, 1, 3);
		world.setBlock(i + 8, j + 8, k + 5, 98, 1, 3);
		world.setBlock(i + 8, j + 8, k + 6, 98, 1, 3);
		world.setBlock(i + 8, j + 8, k + 7, 98, 1, 3);
		world.setBlock(i + 8, j + 8, k + 8, 98, 1, 3);
		world.setBlock(i + 8, j + 8, k + 9, 98, 1, 3);
		world.setBlock(i + 8, j + 8, k + 10, 98, 1, 3);
		world.setBlock(i + 8, j + 8, k + 11, 98, 1, 3);
		world.setBlock(i + 8, j + 8, k + 12, 98, 1, 3);
		world.setBlock(i + 8, j + 8, k + 13, 98, 1, 3);
		world.setBlock(i + 8, j + 8, k + 14, 98, 1, 3);
		world.setBlock(i + 8, j + 8, k + 15, 98, 1, 3);
		world.setBlock(i + 8, j + 8, k + 16, 98, 1, 3);
		world.setBlock(i + 8, j + 8, k + 17, 98, 1, 3);
		world.setBlock(i + 8, j + 8, k + 18, 98, 1, 3);
		world.setBlock(i + 8, j + 8, k + 19, 98, 1, 3);
		world.setBlock(i + 8, j + 8, k + 20, 98, 1, 3);
		world.setBlock(i + 8, j + 8, k + 21, 98, 1, 3);
		world.setBlock(i + 8, j + 8, k + 22, 98, 1, 3);
		world.setBlock(i + 8, j + 8, k + 23, 98, 1, 3);
		world.setBlock(i + 8, j + 8, k + 24, 98, 1, 3);
		world.setBlock(i + 8, j + 8, k + 25, 98, 1, 3);
		world.setBlock(i + 8, j + 8, k + 26, 98, 1, 3);
		world.setBlock(i + 8, j + 8, k + 31, 98, 2, 3);
		world.setBlock(i + 8, j + 9, k + 3, 98, 2, 3);
		world.setBlock(i + 8, j + 9, k + 31, 98, 2, 3);
		world.setBlock(i + 8, j + 10, k + 3, 98, 2, 3);
		world.setBlock(i + 8, j + 10, k + 31, 98, 2, 3);
		world.setBlock(i + 8, j + 11, k + 3, 98, 2, 3);
		world.setBlock(i + 8, j + 11, k + 31, 98, 2, 3);
		world.setBlock(i + 8, j + 12, k + 3, 98, 2, 3);
		world.setBlock(i + 8, j + 12, k + 31, 98, 2, 3);
		world.setBlock(i + 8, j + 13, k + 0, 109, 2, 3);
		world.setBlock(i + 8, j + 13, k + 1, 98, 1, 3);
		world.setBlock(i + 8, j + 13, k + 2, 98, 1, 3);
		world.setBlock(i + 8, j + 13, k + 3, 98, 2, 3);
		world.setBlock(i + 8, j + 13, k + 31, 98, 2, 3);
		world.setBlock(i + 8, j + 13, k + 32, 98, 2, 3);
		world.setBlock(i + 8, j + 13, k + 34, 109, 3, 3);
		world.setBlock(i + 8, j + 14, k + 1, 98, 0, 4);
		world.setBlock(i + 8, j + 14, k + 3, 98, 2, 3);
		world.setBlock(i + 8, j + 14, k + 31, 98, 2, 3);
		world.setBlock(i + 8, j + 14, k + 33, 98, 0, 4);
		world.setBlock(i + 8, j + 15, k + 1, 98, 0, 4);
		world.setBlock(i + 8, j + 15, k + 2, 98, 0, 4);
		world.setBlock(i + 8, j + 15, k + 3, 98, 0, 4);
		world.setBlock(i + 8, j + 15, k + 4, 98, 0, 4);
		world.setBlock(i + 8, j + 15, k + 5, 98, 0, 4);
		world.setBlock(i + 8, j + 15, k + 6, 98, 0, 4);
		world.setBlock(i + 8, j + 15, k + 7, 98, 0, 4);
		world.setBlock(i + 8, j + 15, k + 8, 98, 0, 4);
		world.setBlock(i + 8, j + 15, k + 9, 98, 0, 4);
		world.setBlock(i + 8, j + 15, k + 10, 98, 0, 4);
		world.setBlock(i + 8, j + 15, k + 11, 98, 0, 4);
		world.setBlock(i + 8, j + 15, k + 12, 98, 0, 4);
		world.setBlock(i + 8, j + 15, k + 13, 98, 0, 4);
		world.setBlock(i + 8, j + 15, k + 14, 98, 0, 4);
		world.setBlock(i + 8, j + 15, k + 15, 98, 0, 4);
		world.setBlock(i + 8, j + 15, k + 16, 98, 0, 4);
		world.setBlock(i + 8, j + 15, k + 17, 98, 0, 4);
		world.setBlock(i + 8, j + 15, k + 18, 98, 0, 4);
		world.setBlock(i + 8, j + 15, k + 19, 98, 0, 4);
		world.setBlock(i + 8, j + 15, k + 20, 98, 0, 4);
		world.setBlock(i + 8, j + 15, k + 21, 98, 0, 4);
		world.setBlock(i + 8, j + 15, k + 22, 98, 0, 4);
		world.setBlock(i + 8, j + 15, k + 23, 98, 0, 4);
		world.setBlock(i + 8, j + 15, k + 24, 98, 0, 4);
		world.setBlock(i + 8, j + 15, k + 25, 98, 0, 4);
		world.setBlock(i + 8, j + 15, k + 26, 98, 0, 4);
		world.setBlock(i + 8, j + 15, k + 27, 98, 0, 4);
		world.setBlock(i + 8, j + 15, k + 28, 98, 0, 4);
		world.setBlock(i + 8, j + 15, k + 29, 98, 0, 4);
		world.setBlock(i + 8, j + 15, k + 30, 98, 0, 4);
		world.setBlock(i + 8, j + 15, k + 31, 98, 0, 4);
		world.setBlock(i + 8, j + 15, k + 32, 98, 0, 4);
		world.setBlock(i + 8, j + 15, k + 33, 98, 0, 4);
		world.setBlock(i + 9, j + 0, k + 0, 98, 2, 3);
		world.setBlock(i + 9, j + 0, k + 1, 98, 1, 3);
		world.setBlock(i + 9, j + 0, k + 2, 98, 1, 3);
		world.setBlock(i + 9, j + 0, k + 3, 98, 2, 3);
		world.setBlock(i + 9, j + 0, k + 4, 98, 1, 3);
		world.setBlock(i + 9, j + 0, k + 5, 98, 1, 3);
		world.setBlock(i + 9, j + 0, k + 6, 98, 1, 3);
		world.setBlock(i + 9, j + 0, k + 7, 98, 1, 3);
		world.setBlock(i + 9, j + 0, k + 8, 98, 1, 3);
		world.setBlock(i + 9, j + 0, k + 9, 98, 1, 3);
		world.setBlock(i + 9, j + 0, k + 10, 98, 1, 3);
		world.setBlock(i + 9, j + 0, k + 11, 98, 1, 3);
		world.setBlock(i + 9, j + 0, k + 12, 98, 1, 3);
		world.setBlock(i + 9, j + 0, k + 13, 98, 1, 3);
		world.setBlock(i + 9, j + 0, k + 14, 98, 1, 3);
		world.setBlock(i + 9, j + 0, k + 15, 98, 1, 3);
		world.setBlock(i + 9, j + 0, k + 16, 98, 1, 3);
		world.setBlock(i + 9, j + 0, k + 17, 98, 1, 3);
		world.setBlock(i + 9, j + 0, k + 18, 98, 1, 3);
		world.setBlock(i + 9, j + 0, k + 19, 98, 1, 3);
		world.setBlock(i + 9, j + 0, k + 20, 98, 1, 3);
		world.setBlock(i + 9, j + 0, k + 21, 98, 1, 3);
		world.setBlock(i + 9, j + 0, k + 22, 98, 1, 3);
		world.setBlock(i + 9, j + 0, k + 23, 98, 1, 3);
		world.setBlock(i + 9, j + 0, k + 24, 98, 1, 3);
		world.setBlock(i + 9, j + 0, k + 25, 98, 1, 3);
		world.setBlock(i + 9, j + 0, k + 26, 98, 1, 3);
		world.setBlock(i + 9, j + 0, k + 27, 98, 1, 3);
		world.setBlock(i + 9, j + 0, k + 28, 98, 1, 3);
		world.setBlock(i + 9, j + 0, k + 29, 98, 1, 3);
		world.setBlock(i + 9, j + 0, k + 30, 98, 1, 3);
		world.setBlock(i + 9, j + 0, k + 31, 98, 1, 3);
		world.setBlock(i + 9, j + 0, k + 32, 98, 1, 3);
		world.setBlock(i + 9, j + 0, k + 33, 98, 1, 3);
		world.setBlock(i + 9, j + 0, k + 34, 98, 0, 4);
		world.setBlock(i + 9, j + 1, k + 3, 98, 2, 3);
		world.setBlock(i + 9, j + 1, k + 4, 98, 1, 3);
		world.setBlock(i + 9, j + 1, k + 5, 98, 1, 3);
		world.setBlock(i + 9, j + 1, k + 6, 98, 1, 3);
		world.setBlock(i + 9, j + 1, k + 7, 98, 1, 3);
		world.setBlock(i + 9, j + 1, k + 8, 98, 1, 3);
		world.setBlock(i + 9, j + 1, k + 9, 98, 1, 3);
		world.setBlock(i + 9, j + 1, k + 10, 98, 1, 3);
		world.setBlock(i + 9, j + 1, k + 11, 98, 1, 3);
		world.setBlock(i + 9, j + 1, k + 12, 98, 1, 3);
		world.setBlock(i + 9, j + 1, k + 13, 98, 1, 3);
		world.setBlock(i + 9, j + 1, k + 14, 98, 1, 3);
		world.setBlock(i + 9, j + 1, k + 15, 98, 1, 3);
		world.setBlock(i + 9, j + 1, k + 16, 98, 1, 3);
		world.setBlock(i + 9, j + 1, k + 17, 98, 1, 3);
		world.setBlock(i + 9, j + 1, k + 18, 98, 1, 3);
		world.setBlock(i + 9, j + 1, k + 19, 98, 1, 3);
		world.setBlock(i + 9, j + 1, k + 20, 98, 1, 3);
		world.setBlock(i + 9, j + 1, k + 21, 98, 1, 3);
		world.setBlock(i + 9, j + 1, k + 22, 98, 1, 3);
		world.setBlock(i + 9, j + 1, k + 23, 98, 1, 3);
		world.setBlock(i + 9, j + 1, k + 24, 98, 1, 3);
		world.setBlock(i + 9, j + 1, k + 25, 98, 1, 3);
		world.setBlock(i + 9, j + 1, k + 26, 98, 1, 3);
		world.setBlock(i + 9, j + 1, k + 27, 98, 1, 3);
		world.setBlock(i + 9, j + 1, k + 28, 98, 1, 3);
		world.setBlock(i + 9, j + 1, k + 29, 98, 1, 3);
		world.setBlock(i + 9, j + 1, k + 30, 98, 1, 3);
		world.setBlock(i + 9, j + 1, k + 31, 98, 2, 3);
		world.setBlock(i + 9, j + 2, k + 3, 98, 2, 3);
		world.setBlock(i + 9, j + 2, k + 4, 98, 1, 3);
		world.setBlock(i + 9, j + 2, k + 5, 98, 1, 3);
		world.setBlock(i + 9, j + 2, k + 6, 98, 1, 3);
		world.setBlock(i + 9, j + 2, k + 7, 98, 1, 3);
		world.setBlock(i + 9, j + 2, k + 8, 98, 1, 3);
		world.setBlock(i + 9, j + 2, k + 9, 98, 1, 3);
		world.setBlock(i + 9, j + 2, k + 10, 98, 1, 3);
		world.setBlock(i + 9, j + 2, k + 11, 98, 1, 3);
		world.setBlock(i + 9, j + 2, k + 12, 98, 1, 3);
		world.setBlock(i + 9, j + 2, k + 13, 98, 1, 3);
		world.setBlock(i + 9, j + 2, k + 14, 98, 1, 3);
		world.setBlock(i + 9, j + 2, k + 15, 98, 1, 3);
		world.setBlock(i + 9, j + 2, k + 16, 98, 1, 3);
		world.setBlock(i + 9, j + 2, k + 17, 98, 1, 3);
		world.setBlock(i + 9, j + 2, k + 18, 98, 1, 3);
		world.setBlock(i + 9, j + 2, k + 19, 98, 1, 3);
		world.setBlock(i + 9, j + 2, k + 20, 98, 1, 3);
		world.setBlock(i + 9, j + 2, k + 21, 98, 1, 3);
		world.setBlock(i + 9, j + 2, k + 22, 98, 1, 3);
		world.setBlock(i + 9, j + 2, k + 23, 98, 1, 3);
		world.setBlock(i + 9, j + 2, k + 24, 98, 1, 3);
		world.setBlock(i + 9, j + 2, k + 25, 98, 1, 3);
		world.setBlock(i + 9, j + 2, k + 26, 98, 1, 3);
		world.setBlock(i + 9, j + 2, k + 27, 98, 1, 3);
		world.setBlock(i + 9, j + 2, k + 28, 98, 1, 3);
		world.setBlock(i + 9, j + 2, k + 29, 98, 1, 3);
		world.setBlock(i + 9, j + 2, k + 30, 98, 1, 3);
		world.setBlock(i + 9, j + 2, k + 31, 98, 2, 3);
		world.setBlock(i + 9, j + 3, k + 3, 98, 2, 3);
		world.setBlock(i + 9, j + 3, k + 31, 98, 2, 3);
		world.setBlock(i + 9, j + 4, k + 3, 98, 2, 3);
		world.setBlock(i + 9, j + 4, k + 31, 98, 2, 3);
		world.setBlock(i + 9, j + 5, k + 3, 98, 2, 3);
		world.setBlock(i + 9, j + 5, k + 27, 109, 5, 3);
		world.setBlock(i + 9, j + 5, k + 28, 109, 5, 3);
		world.setBlock(i + 9, j + 5, k + 31, 98, 2, 3);
		world.setBlock(i + 9, j + 6, k + 3, 98, 2, 3);
		world.setBlock(i + 9, j + 6, k + 27, 109, 0, 4);
		world.setBlock(i + 9, j + 6, k + 28, 109, 0, 4);
		world.setBlock(i + 9, j + 6, k + 31, 98, 2, 3);
		world.setBlock(i + 9, j + 7, k + 0, 98, 3, 3);
		world.setBlock(i + 9, j + 7, k + 1, 98, 1, 3);
		world.setBlock(i + 9, j + 7, k + 2, 98, 1, 3);
		world.setBlock(i + 9, j + 7, k + 3, 98, 2, 3);
		world.setBlock(i + 9, j + 7, k + 12, 89, 0, 4);
		world.setBlock(i + 9, j + 7, k + 31, 98, 2, 3);
		world.setBlock(i + 9, j + 7, k + 32, 98, 1, 3);
		world.setBlock(i + 9, j + 7, k + 33, 98, 1, 3);
		world.setBlock(i + 9, j + 7, k + 34, 98, 3, 3);
		world.setBlock(i + 9, j + 8, k + 3, 98, 2, 3);
		world.setBlock(i + 9, j + 8, k + 4, 98, 1, 3);
		world.setBlock(i + 9, j + 8, k + 5, 98, 1, 3);
		world.setBlock(i + 9, j + 8, k + 6, 98, 1, 3);
		world.setBlock(i + 9, j + 8, k + 7, 98, 1, 3);
		world.setBlock(i + 9, j + 8, k + 8, 98, 1, 3);
		world.setBlock(i + 9, j + 8, k + 9, 98, 1, 3);
		world.setBlock(i + 9, j + 8, k + 10, 98, 1, 3);
		world.setBlock(i + 9, j + 8, k + 11, 98, 1, 3);
		world.setBlock(i + 9, j + 8, k + 12, 98, 1, 3);
		world.setBlock(i + 9, j + 8, k + 13, 98, 1, 3);
		world.setBlock(i + 9, j + 8, k + 14, 98, 1, 3);
		world.setBlock(i + 9, j + 8, k + 15, 98, 1, 3);
		world.setBlock(i + 9, j + 8, k + 16, 98, 1, 3);
		world.setBlock(i + 9, j + 8, k + 17, 98, 1, 3);
		world.setBlock(i + 9, j + 8, k + 18, 98, 1, 3);
		world.setBlock(i + 9, j + 8, k + 19, 98, 1, 3);
		world.setBlock(i + 9, j + 8, k + 20, 98, 1, 3);
		world.setBlock(i + 9, j + 8, k + 21, 98, 1, 3);
		world.setBlock(i + 9, j + 8, k + 22, 98, 1, 3);
		world.setBlock(i + 9, j + 8, k + 23, 98, 1, 3);
		world.setBlock(i + 9, j + 8, k + 24, 98, 1, 3);
		world.setBlock(i + 9, j + 8, k + 25, 98, 1, 3);
		world.setBlock(i + 9, j + 8, k + 26, 98, 1, 3);
		world.setBlock(i + 9, j + 8, k + 31, 98, 2, 3);
		world.setBlock(i + 9, j + 9, k + 3, 98, 2, 3);
		world.setBlock(i + 9, j + 9, k + 31, 98, 2, 3);
		world.setBlock(i + 9, j + 10, k + 3, 98, 2, 3);
		world.setBlock(i + 9, j + 10, k + 31, 98, 2, 3);
		world.setBlock(i + 9, j + 11, k + 3, 98, 2, 3);
		world.setBlock(i + 9, j + 11, k + 31, 98, 2, 3);
		world.setBlock(i + 9, j + 12, k + 3, 98, 2, 3);
		world.setBlock(i + 9, j + 12, k + 31, 98, 2, 3);
		world.setBlock(i + 9, j + 13, k + 0, 109, 2, 3);
		world.setBlock(i + 9, j + 13, k + 1, 98, 1, 3);
		world.setBlock(i + 9, j + 13, k + 2, 98, 1, 3);
		world.setBlock(i + 9, j + 13, k + 3, 98, 2, 3);
		world.setBlock(i + 9, j + 13, k + 31, 98, 2, 3);
		world.setBlock(i + 9, j + 13, k + 32, 98, 2, 3);
		world.setBlock(i + 9, j + 13, k + 34, 109, 3, 3);
		world.setBlock(i + 9, j + 14, k + 1, 98, 0, 4);
		world.setBlock(i + 9, j + 14, k + 3, 98, 2, 3);
		world.setBlock(i + 9, j + 14, k + 31, 98, 2, 3);
		world.setBlock(i + 9, j + 14, k + 33, 98, 0, 4);
		world.setBlock(i + 9, j + 15, k + 1, 98, 0, 4);
		world.setBlock(i + 9, j + 15, k + 3, 98, 2, 3);
		world.setBlock(i + 9, j + 15, k + 31, 98, 2, 3);
		world.setBlock(i + 9, j + 15, k + 33, 98, 0, 4);
		world.setBlock(i + 9, j + 16, k + 1, 44, 5, 3);
		world.setBlock(i + 9, j + 16, k + 2, 44, 5, 3);
		world.setBlock(i + 9, j + 16, k + 3, 44, 5, 3);
		world.setBlock(i + 9, j + 16, k + 4, 44, 5, 3);
		world.setBlock(i + 9, j + 16, k + 5, 44, 5, 3);
		world.setBlock(i + 9, j + 16, k + 6, 44, 5, 3);
		world.setBlock(i + 9, j + 16, k + 7, 44, 5, 3);
		world.setBlock(i + 9, j + 16, k + 8, 44, 5, 3);
		world.setBlock(i + 9, j + 16, k + 9, 44, 5, 3);
		world.setBlock(i + 9, j + 16, k + 10, 44, 5, 3);
		world.setBlock(i + 9, j + 16, k + 11, 44, 5, 3);
		world.setBlock(i + 9, j + 16, k + 12, 44, 5, 3);
		world.setBlock(i + 9, j + 16, k + 13, 44, 5, 3);
		world.setBlock(i + 9, j + 16, k + 14, 44, 5, 3);
		world.setBlock(i + 9, j + 16, k + 15, 44, 5, 3);
		world.setBlock(i + 9, j + 16, k + 16, 44, 5, 3);
		world.setBlock(i + 9, j + 16, k + 17, 44, 5, 3);
		world.setBlock(i + 9, j + 16, k + 18, 44, 5, 3);
		world.setBlock(i + 9, j + 16, k + 19, 44, 5, 3);
		world.setBlock(i + 9, j + 16, k + 20, 44, 5, 3);
		world.setBlock(i + 9, j + 16, k + 21, 44, 5, 3);
		world.setBlock(i + 9, j + 16, k + 22, 44, 5, 3);
		world.setBlock(i + 9, j + 16, k + 23, 44, 5, 3);
		world.setBlock(i + 9, j + 16, k + 24, 44, 5, 3);
		world.setBlock(i + 9, j + 16, k + 25, 44, 5, 3);
		world.setBlock(i + 9, j + 16, k + 26, 44, 5, 3);
		world.setBlock(i + 9, j + 16, k + 27, 44, 5, 3);
		world.setBlock(i + 9, j + 16, k + 28, 44, 5, 3);
		world.setBlock(i + 9, j + 16, k + 29, 44, 5, 3);
		world.setBlock(i + 9, j + 16, k + 30, 44, 5, 3);
		world.setBlock(i + 9, j + 16, k + 31, 44, 5, 3);
		world.setBlock(i + 9, j + 16, k + 32, 44, 5, 3);
		world.setBlock(i + 9, j + 16, k + 33, 44, 5, 3);
		world.setBlock(i + 10, j + 0, k + 0, 109, 2, 3);
		world.setBlock(i + 10, j + 0, k + 1, 98, 3, 3);
		world.setBlock(i + 10, j + 0, k + 2, 98, 1, 3);
		world.setBlock(i + 10, j + 0, k + 3, 98, 2, 3);
